Workbook

Sheet Sheet2
A1: CASEID | B1: COURTID | C1: NATURECODE | D1: CATEGORY | E1: CASENUM | F1: CASETITLE | G1: DTFILED | H1: DTRECEIVED | I1: DTTRANSFER | J1: TRANSFER | K1: CASETYPE | L1: CLOSEDATE | M1: CLOSETAG | N1: CLOSEDET | O1: NATUREREM | P1: IAMOUNT | Q1: IWEIGHT | R1: CSTATUS | S1: CSTATUSID | T1: CLOSESTAT | U1: CREATEBY | V1: CREATEDT | W1: MODIFYBY | X1: MODIFYDT
A2: {=_xludf.IFNA(INDEX(Sheet6!A:A, MATCH($E2, Sheet6!$E:$E, 0)),"N/A")} -> #NAME? | B2: {=_xludf.IFNA(INDEX(Sheet6!B:B, MATCH($E2, Sheet6!$E:$E, 0)),"N/A")} -> #NAME? | C2: {=_xludf.IFNA(INDEX(Sheet6!C:C, MATCH($E2, Sheet6!$E:$E, 0)),"N/A")} -> #NAME? | D2: {=_xludf.IFNA(INDEX(Sheet6!D:D, MATCH($E2, Sheet6!$E:$E, 0)),"N/A")} -> #NAME? | E2: 3737 | F2: PEOPLE OF THE PHILIPPINES VS. JOVENVIO TINUN-OGAN A.K.A. DATU MANTIMONGMONG | G2: 38505 | H2: 38505 | I2: {=_xludf.IFNA(INDEX(Sheet6!I:I, MATCH($E2, Sheet6!$E:$E, 0)),"N/A")} -> #NAME? | J2: {=_xludf.IFNA(INDEX(Sheet6!J:J, MATCH($E2, Sheet6!$E:$E, 0)),"N/A")} -> #NAME? | K2: {=_xludf.IFNA(INDEX(Sheet6!K:K, MATCH($E2, Sheet6!$E:$E, 0)),"N/A")} -> #NAME? | L2: {=_xludf.IFNA(INDEX(Sheet6!L:L, MATCH($E2, Sheet6!$E:$E, 0)),"N/A")} -> #NAME? | M2: {=_xludf.IFNA(INDEX(Sheet6!M:M, MATCH($E2, Sheet6!$E:$E, 0)),"N/A")} -> #NAME? | N2: {=_xludf.IFNA(INDEX(Sheet6!N:N, MATCH($E2, Sheet6!$E:$E, 0)),"N/A")} -> #NAME? | P2: {=_xludf.IFNA(INDEX(Sheet6!P:P, MATCH($E2, Sheet6!$E:$E, 0)),"N/A")} -> #NAME? | Q2: {=_xludf.IFNA(INDEX(Sheet6!Q:Q, MATCH($E2, Sheet6!$E:$E, 0)),"N/A")} -> #NAME? | R2: {=_xludf.IFNA(INDEX(Sheet6!R:R, MATCH($E2, Sheet6!$E:$E, 0)),"N/A")} -> #NAME? | S2: {=_xludf.IFNA(INDEX(Sheet6!S:S, MATCH($E2, Sheet6!$E:$E, 0)),"N/A")} -> #NAME? | T2: {=_xludf.IFNA(INDEX(Sheet6!T:T, MATCH($E2, Sheet6!$E:$E, 0)),"N/A")} -> #NAME? | U2: {=_xludf.IFNA(INDEX(Sheet6!U:U, MATCH($E2, Sheet6!$E:$E, 0)),"N/A")} -> #NAME? | V2: {=_xludf.IFNA(INDEX(Sheet6!V:V, MATCH($E2, Sheet6!$E:$E, 0)),"N/A")} -> #NAME? | W2: {=_xludf.IFNA(INDEX(Sheet6!W:W, MATCH($E2, Sheet6!$E:$E, 0)),"N/A")} -> #NAME? | X2: {=_xludf.IFNA(INDEX(Sheet6!X:X, MATCH($E2, Sheet6!$E:$E, 0)),"N/A")} -> #NAME?
A3: {=_xludf.IFNA(INDEX(Sheet6!A:A, MATCH($E3, Sheet6!$E:$E, 0)),"N/A")} -> #NAME? | B3: {=_xludf.IFNA(INDEX(Sheet6!B:B, MATCH($E3, Sheet6!$E:$E, 0)),"N/A")} -> #NAME? | C3: {=_xludf.IFNA(INDEX(Sheet6!C:C, MATCH($E3, Sheet6!$E:$E, 0)),"N/A")} -> #NAME? | D3: {=_xludf.IFNA(INDEX(Sheet6!D:D, MATCH($E3, Sheet6!$E:$E, 0)),"N/A")} -> #NAME? | E3: 3878 | F3: PEOPLE OF THE PHILIPPINES VS. RENE JAVIER | G3: 39818 | H3: 39818 | I3: {=_xludf.IFNA(INDEX(Sheet6!I:I, MATCH($E3, Sheet6!$E:$E, 0)),"N/A")} -> #NAME? | J3: {=_xludf.IFNA(INDEX(Sheet6!J:J, MATCH($E3, Sheet6!$E:$E, 0)),"N/A")} -> #NAME? | K3: {=_xludf.IFNA(INDEX(Sheet6!K:K, MATCH($E3, Sheet6!$E:$E, 0)),"N/A")} -> #NAME? | L3: {=_xludf.IFNA(INDEX(Sheet6!L:L, MATCH($E3, Sheet6!$E:$E, 0)),"N/A")} -> #NAME? | M3: {=_xludf.IFNA(INDEX(Sheet6!M:M, MATCH($E3, Sheet6!$E:$E, 0)),"N/A")} -> #NAME? | N3: {=_xludf.IFNA(INDEX(Sheet6!N:N, MATCH($E3, Sheet6!$E:$E, 0)),"N/A")} -> #NAME? | O3: THEFT | P3: {=_xludf.IFNA(INDEX(Sheet6!P:P, MATCH($E3, Sheet6!$E:$E, 0)),"N/A")} -> #NAME? | Q3: {=_xludf.IFNA(INDEX(Sheet6!Q:Q, MATCH($E3, Sheet6!$E:$E, 0)),"N/A")} -> #NAME? | R3: {=_xludf.IFNA(INDEX(Sheet6!R:R, MATCH($E3, Sheet6!$E:$E, 0)),"N/A")} -> #NAME? | S3: {=_xludf.IFNA(INDEX(Sheet6!S:S, MATCH($E3, Sheet6!$E:$E, 0)),"N/A")} -> #NAME? | T3: {=_xludf.IFNA(INDEX(Sheet6!T:T, MATCH($E3, Sheet6!$E:$E, 0)),"N/A")} -> #NAME? | U3: {=_xludf.IFNA(INDEX(Sheet6!U:U, MATCH($E3, Sheet6!$E:$E, 0)),"N/A")} -> #NAME? | V3: {=_xludf.IFNA(INDEX(Sheet6!V:V, MATCH($E3, Sheet6!$E:$E, 0)),"N/A")} -> #NAME? | W3: {=_xludf.IFNA(INDEX(Sheet6!W:W, MATCH($E3, Sheet6!$E:$E, 0)),"N/A")} -> #NAME? | X3: {=_xludf.IFNA(INDEX(Sheet6!X:X, MATCH($E3, Sheet6!$E:$E, 0)),"N/A")} -> #NAME?
A4: {=_xludf.IFNA(INDEX(Sheet6!A:A, MATCH($E4, Sheet6!$E:$E, 0)),"N/A")} -> #NAME? | B4: {=_xludf.IFNA(INDEX(Sheet6!B:B, MATCH($E4, Sheet6!$E:$E, 0)),"N/A")} -> #NAME? | C4: {=_xludf.IFNA(INDEX(Sheet6!C:C, MATCH($E4, Sheet6!$E:$E, 0)),"N/A")} -> #NAME? | D4: {=_xludf.IFNA(INDEX(Sheet6!D:D, MATCH($E4, Sheet6!$E:$E, 0)),"N/A")} -> #NAME? | E4: 3879 | F4: PEOPLE OF THE PHILIPPINES VS. FELIX GARDOSE & FELIPE CARDOSE | G4: 39836 | H4: 39836 | I4: {=_xludf.IFNA(INDEX(Sheet6!I:I, MATCH($E4, Sheet6!$E:$E, 0)),"N/A")} -> #NAME? | J4: {=_xludf.IFNA(INDEX(Sheet6!J:J, MATCH($E4, Sheet6!$E:$E, 0)),"N/A")} -> #NAME? | K4: {=_xludf.IFNA(INDEX(Sheet6!K:K, MATCH($E4, Sheet6!$E:$E, 0)),"N/A")} -> #NAME? | L4: {=_xludf.IFNA(INDEX(Sheet6!L:L, MATCH($E4, Sheet6!$E:$E, 0)),"N/A")} -> #NAME? | M4: {=_xludf.IFNA(INDEX(Sheet6!M:M, MATCH($E4, Sheet6!$E:$E, 0)),"N/A")} -> #NAME? | N4: {=_xludf.IFNA(INDEX(Sheet6!N:N, MATCH($E4, Sheet6!$E:$E, 0)),"N/A")} -> #NAME? | O4: ATTEMPTED QUALIFIED THEFT | P4: {=_xludf.IFNA(INDEX(Sheet6!P:P, MATCH($E4, Sheet6!$E:$E, 0)),"N/A")} -> #NAME? | Q4: {=_xludf.IFNA(INDEX(Sheet6!Q:Q, MATCH($E4, Sheet6!$E:$E, 0)),"N/A")} -> #NAME? | R4: {=_xludf.IFNA(INDEX(Sheet6!R:R, MATCH($E4, Sheet6!$E:$E, 0)),"N/A")} -> #NAME? | S4: {=_xludf.IFNA(INDEX(Sheet6!S:S, MATCH($E4, Sheet6!$E:$E, 0)),"N/A")} -> #NAME? | T4: {=_xludf.IFNA(INDEX(Sheet6!T:T, MATCH($E4, Sheet6!$E:$E, 0)),"N/A")} -> #NAME? | U4: {=_xludf.IFNA(INDEX(Sheet6!U:U, MATCH($E4, Sheet6!$E:$E, 0)),"N/A")} -> #NAME? | V4: {=_xludf.IFNA(INDEX(Sheet6!V:V, MATCH($E4, Sheet6!$E:$E, 0)),"N/A")} -> #NAME? | W4: {=_xludf.IFNA(INDEX(Sheet6!W:W, MATCH($E4, Sheet6!$E:$E, 0)),"N/A")} -> #NAME? | X4: {=_xludf.IFNA(INDEX(Sheet6!X:X, MATCH($E4, Sheet6!$E:$E, 0)),"N/A")} -> #NAME?
A5: {=_xludf.IFNA(INDEX(Sheet6!A:A, MATCH($E5, Sheet6!$E:$E, 0)),"N/A")} -> #NAME? | B5: {=_xludf.IFNA(INDEX(Sheet6!B:B, MATCH($E5, Sheet6!$E:$E, 0)),"N/A")} -> #NAME? | C5: {=_xludf.IFNA(INDEX(Sheet6!C:C, MATCH($E5, Sheet6!$E:$E, 0)),"N/A")} -> #NAME? | D5: {=_xludf.IFNA(INDEX(Sheet6!D:D, MATCH($E5, Sheet6!$E:$E, 0)),"N/A")} -> #NAME? | E5: 3880 | F5: PEOPLE OF THE PHILIPPINES VS. JERRY BEDRA, JR. | G5: 39847 | H5: 39847 | I5: {=_xludf.IFNA(INDEX(Sheet6!I:I, MATCH($E5, Sheet6!$E:$E, 0)),"N/A")} -> #NAME? | J5: {=_xludf.IFNA(INDEX(Sheet6!J:J, MATCH($E5, Sheet6!$E:$E, 0)),"N/A")} -> #NAME? | K5: {=_xludf.IFNA(INDEX(Sheet6!K:K, MATCH($E5, Sheet6!$E:$E, 0)),"N/A")} -> #NAME? | L5: {=_xludf.IFNA(INDEX(Sheet6!L:L, MATCH($E5, Sheet6!$E:$E, 0)),"N/A")} -> #NAME? | M5: {=_xludf.IFNA(INDEX(Sheet6!M:M, MATCH($E5, Sheet6!$E:$E, 0)),"N/A")} -> #NAME? | N5: {=_xludf.IFNA(INDEX(Sheet6!N:N, MATCH($E5, Sheet6!$E:$E, 0)),"N/A")} -> #NAME? | O5: DIRECT ASSAULT | P5: {=_xludf.IFNA(INDEX(Sheet6!P:P, MATCH($E5, Sheet6!$E:$E, 0)),"N/A")} -> #NAME? | Q5: {=_xludf.IFNA(INDEX(Sheet6!Q:Q, MATCH($E5, Sheet6!$E:$E, 0)),"N/A")} -> #NAME? | R5: {=_xludf.IFNA(INDEX(Sheet6!R:R, MATCH($E5, Sheet6!$E:$E, 0)),"N/A")} -> #NAME? | S5: {=_xludf.IFNA(INDEX(Sheet6!S:S, MATCH($E5, Sheet6!$E:$E, 0)),"N/A")} -> #NAME? | T5: {=_xludf.IFNA(INDEX(Sheet6!T:T, MATCH($E5, Sheet6!$E:$E, 0)),"N/A")} -> #NAME? | U5: {=_xludf.IFNA(INDEX(Sheet6!U:U, MATCH($E5, Sheet6!$E:$E, 0)),"N/A")} -> #NAME? | V5: {=_xludf.IFNA(INDEX(Sheet6!V:V, MATCH($E5, Sheet6!$E:$E, 0)),"N/A")} -> #NAME? | W5: {=_xludf.IFNA(INDEX(Sheet6!W:W, MATCH($E5, Sheet6!$E:$E, 0)),"N/A")} -> #NAME? | X5: {=_xludf.IFNA(INDEX(Sheet6!X:X, MATCH($E5, Sheet6!$E:$E, 0)),"N/A")} -> #NAME?
A6: {=_xludf.IFNA(INDEX(Sheet6!A:A, MATCH($E6, Sheet6!$E:$E, 0)),"N/A")} -> #NAME? | B6: {=_xludf.IFNA(INDEX(Sheet6!B:B, MATCH($E6, Sheet6!$E:$E, 0)),"N/A")} -> #NAME? | C6: {=_xludf.IFNA(INDEX(Sheet6!C:C, MATCH($E6, Sheet6!$E:$E, 0)),"N/A")} -> #NAME? | D6: {=_xludf.IFNA(INDEX(Sheet6!D:D, MATCH($E6, Sheet6!$E:$E, 0)),"N/A")} -> #NAME? | E6: 3881 | F6: PEOPLE OF THE PHILIPPINES VS. MARCO CARLO GUINDULMAN & RICO GUINDULMAN | G6: 39847 | H6: 39847 | I6: {=_xludf.IFNA(INDEX(Sheet6!I:I, MATCH($E6, Sheet6!$E:$E, 0)),"N/A")} -> #NAME? | J6: {=_xludf.IFNA(INDEX(Sheet6!J:J, MATCH($E6, Sheet6!$E:$E, 0)),"N/A")} -> #NAME? | K6: {=_xludf.IFNA(INDEX(Sheet6!K:K, MATCH($E6, Sheet6!$E:$E, 0)),"N/A")} -> #NAME? | L6: {=_xludf.IFNA(INDEX(Sheet6!L:L, MATCH($E6, Sheet6!$E:$E, 0)),"N/A")} -> #NAME? | M6: {=_xludf.IFNA(INDEX(Sheet6!M:M, MATCH($E6, Sheet6!$E:$E, 0)),"N/A")} -> #NAME? | N6: {=_xludf.IFNA(INDEX(Sheet6!N:N, MATCH($E6, Sheet6!$E:$E, 0)),"N/A")} -> #NAME? | O6: SLIGHT PHYSICAN INJURIES | P6: {=_xludf.IFNA(INDEX(Sheet6!P:P, MATCH($E6, Sheet6!$E:$E, 0)),"N/A")} -> #NAME? | Q6: {=_xludf.IFNA(INDEX(Sheet6!Q:Q, MATCH($E6, Sheet6!$E:$E, 0)),"N/A")} -> #NAME? | R6: {=_xludf.IFNA(INDEX(Sheet6!R:R, MATCH($E6, Sheet6!$E:$E, 0)),"N/A")} -> #NAME? | S6: {=_xludf.IFNA(INDEX(Sheet6!S:S, MATCH($E6, Sheet6!$E:$E, 0)),"N/A")} -> #NAME? | T6: {=_xludf.IFNA(INDEX(Sheet6!T:T, MATCH($E6, Sheet6!$E:$E, 0)),"N/A")} -> #NAME? | U6: {=_xludf.IFNA(INDEX(Sheet6!U:U, MATCH($E6, Sheet6!$E:$E, 0)),"N/A")} -> #NAME? | V6: {=_xludf.IFNA(INDEX(Sheet6!V:V, MATCH($E6, Sheet6!$E:$E, 0)),"N/A")} -> #NAME? | W6: {=_xludf.IFNA(INDEX(Sheet6!W:W, MATCH($E6, Sheet6!$E:$E, 0)),"N/A")} -> #NAME? | X6: {=_xludf.IFNA(INDEX(Sheet6!X:X, MATCH($E6, Sheet6!$E:$E, 0)),"N/A")} -> #NAME?
A7: {=_xludf.IFNA(INDEX(Sheet6!A:A, MATCH($E7, Sheet6!$E:$E, 0)),"N/A")} -> #NAME? | B7: {=_xludf.IFNA(INDEX(Sheet6!B:B, MATCH($E7, Sheet6!$E:$E, 0)),"N/A")} -> #NAME? | C7: {=_xludf.IFNA(INDEX(Sheet6!C:C, MATCH($E7, Sheet6!$E:$E, 0)),"N/A")} -> #NAME? | D7: {=_xludf.IFNA(INDEX(Sheet6!D:D, MATCH($E7, Sheet6!$E:$E, 0)),"N/A")} -> #NAME? | E7: 3882 | F7: PEOPLE OF THE PHILIPPINES VS. JUNMARK T. MILLAN | G7: 39876 | H7: 39876 | I7: {=_xludf.IFNA(INDEX(Sheet6!I:I, MATCH($E7, Sheet6!$E:$E, 0)),"N/A")} -> #NAME? | J7: {=_xludf.IFNA(INDEX(Sheet6!J:J, MATCH($E7, Sheet6!$E:$E, 0)),"N/A")} -> #NAME? | K7: {=_xludf.IFNA(INDEX(Sheet6!K:K, MATCH($E7, Sheet6!$E:$E, 0)),"N/A")} -> #NAME? | L7: {=_xludf.IFNA(INDEX(Sheet6!L:L, MATCH($E7, Sheet6!$E:$E, 0)),"N/A")} -> #NAME? | M7: {=_xludf.IFNA(INDEX(Sheet6!M:M, MATCH($E7, Sheet6!$E:$E, 0)),"N/A")} -> #NAME? | N7: {=_xludf.IFNA(INDEX(Sheet6!N:N, MATCH($E7, Sheet6!$E:$E, 0)),"N/A")} -> #NAME? | O7: VIOLATION OF SEC. 1 B.BP BLG 6 | P7: {=_xludf.IFNA(INDEX(Sheet6!P:P, MATCH($E7, Sheet6!$E:$E, 0)),"N/A")} -> #NAME? | Q7: {=_xludf.IFNA(INDEX(Sheet6!Q:Q, MATCH($E7, Sheet6!$E:$E, 0)),"N/A")} -> #NAME? | R7: {=_xludf.IFNA(INDEX(Sheet6!R:R, MATCH($E7, Sheet6!$E:$E, 0)),"N/A")} -> #NAME? | S7: {=_xludf.IFNA(INDEX(Sheet6!S:S, MATCH($E7, Sheet6!$E:$E, 0)),"N/A")} -> #NAME? | T7: {=_xludf.IFNA(INDEX(Sheet6!T:T, MATCH($E7, Sheet6!$E:$E, 0)),"N/A")} -> #NAME? | U7: {=_xludf.IFNA(INDEX(Sheet6!U:U, MATCH($E7, Sheet6!$E:$E, 0)),"N/A")} -> #NAME? | V7: {=_xludf.IFNA(INDEX(Sheet6!V:V, MATCH($E7, Sheet6!$E:$E, 0)),"N/A")} -> #NAME? | W7: {=_xludf.IFNA(INDEX(Sheet6!W:W, MATCH($E7, Sheet6!$E:$E, 0)),"N/A")} -> #NAME? | X7: {=_xludf.IFNA(INDEX(Sheet6!X:X, MATCH($E7, Sheet6!$E:$E, 0)),"N/A")} -> #NAME?
A8: {=_xludf.IFNA(INDEX(Sheet6!A:A, MATCH($E8, Sheet6!$E:$E, 0)),"N/A")} -> #NAME? | B8: {=_xludf.IFNA(INDEX(Sheet6!B:B, MATCH($E8, Sheet6!$E:$E, 0)),"N/A")} -> #NAME? | C8: {=_xludf.IFNA(INDEX(Sheet6!C:C, MATCH($E8, Sheet6!$E:$E, 0)),"N/A")} -> #NAME? | D8: {=_xludf.IFNA(INDEX(Sheet6!D:D, MATCH($E8, Sheet6!$E:$E, 0)),"N/A")} -> #NAME? | E8: 3883 | F8: PEOPLE OF THE PHILIPPINES VS. VIRQILIO LANCHENIBRE | G8: 39883 | H8: 39883 | I8: {=_xludf.IFNA(INDEX(Sheet6!I:I, MATCH($E8, Sheet6!$E:$E, 0)),"N/A")} -> #NAME? | J8: {=_xludf.IFNA(INDEX(Sheet6!J:J, MATCH($E8, Sheet6!$E:$E, 0)),"N/A")} -> #NAME? | K8: {=_xludf.IFNA(INDEX(Sheet6!K:K, MATCH($E8, Sheet6!$E:$E, 0)),"N/A")} -> #NAME? | L8: {=_xludf.IFNA(INDEX(Sheet6!L:L, MATCH($E8, Sheet6!$E:$E, 0)),"N/A")} -> #NAME? | M8: {=_xludf.IFNA(INDEX(Sheet6!M:M, MATCH($E8, Sheet6!$E:$E, 0)),"N/A")} -> #NAME? | N8: {=_xludf.IFNA(INDEX(Sheet6!N:N, MATCH($E8, Sheet6!$E:$E, 0)),"N/A")} -> #NAME? | O8: ILLEGAL POSSESSION OF FIREARM | P8: {=_xludf.IFNA(INDEX(Sheet6!P:P, MATCH($E8, Sheet6!$E:$E, 0)),"N/A")} -> #NAME? | Q8: {=_xludf.IFNA(INDEX(Sheet6!Q:Q, MATCH($E8, Sheet6!$E:$E, 0)),"N/A")} -> #NAME? | R8: {=_xludf.IFNA(INDEX(Sheet6!R:R, MATCH($E8, Sheet6!$E:$E, 0)),"N/A")} -> #NAME? | S8: {=_xludf.IFNA(INDEX(Sheet6!S:S, MATCH($E8, Sheet6!$E:$E, 0)),"N/A")} -> #NAME? | T8: {=_xludf.IFNA(INDEX(Sheet6!T:T, MATCH($E8, Sheet6!$E:$E, 0)),"N/A")} -> #NAME? | U8: {=_xludf.IFNA(INDEX(Sheet6!U:U, MATCH($E8, Sheet6!$E:$E, 0)),"N/A")} -> #NAME? | V8: {=_xludf.IFNA(INDEX(Sheet6!V:V, MATCH($E8, Sheet6!$E:$E, 0)),"N/A")} -> #NAME? | W8: {=_xludf.IFNA(INDEX(Sheet6!W:W, MATCH($E8, Sheet6!$E:$E, 0)),"N/A")} -> #NAME? | X8: {=_xludf.IFNA(INDEX(Sheet6!X:X, MATCH($E8, Sheet6!$E:$E, 0)),"N/A")} -> #NAME?
A9: {=_xludf.IFNA(INDEX(Sheet6!A:A, MATCH($E9, Sheet6!$E:$E, 0)),"N/A")} -> #NAME? | B9: {=_xludf.IFNA(INDEX(Sheet6!B:B, MATCH($E9, Sheet6!$E:$E, 0)),"N/A")} -> #NAME? | C9: {=_xludf.IFNA(INDEX(Sheet6!C:C, MATCH($E9, Sheet6!$E:$E, 0)),"N/A")} -> #NAME? | D9: {=_xludf.IFNA(INDEX(Sheet6!D:D, MATCH($E9, Sheet6!$E:$E, 0)),"N/A")} -> #NAME? | E9: 3884 | F9: PEOPLE OF THE PHILIPPINES VS. CRISCENSIA JABIAN | G9: 39918 | H9: 39918 | I9: {=_xludf.IFNA(INDEX(Sheet6!I:I, MATCH($E9, Sheet6!$E:$E, 0)),"N/A")} -> #NAME? | J9: {=_xludf.IFNA(INDEX(Sheet6!J:J, MATCH($E9, Sheet6!$E:$E, 0)),"N/A")} -> #NAME? | K9: {=_xludf.IFNA(INDEX(Sheet6!K:K, MATCH($E9, Sheet6!$E:$E, 0)),"N/A")} -> #NAME? | L9: {=_xludf.IFNA(INDEX(Sheet6!L:L, MATCH($E9, Sheet6!$E:$E, 0)),"N/A")} -> #NAME? | M9: {=_xludf.IFNA(INDEX(Sheet6!M:M, MATCH($E9, Sheet6!$E:$E, 0)),"N/A")} -> #NAME? | N9: {=_xludf.IFNA(INDEX(Sheet6!N:N, MATCH($E9, Sheet6!$E:$E, 0)),"N/A")} -> #NAME? | O9: ESTAFA | P9: {=_xludf.IFNA(INDEX(Sheet6!P:P, MATCH($E9, Sheet6!$E:$E, 0)),"N/A")} -> #NAME? | Q9: {=_xludf.IFNA(INDEX(Sheet6!Q:Q, MATCH($E9, Sheet6!$E:$E, 0)),"N/A")} -> #NAME? | R9: {=_xludf.IFNA(INDEX(Sheet6!R:R, MATCH($E9, Sheet6!$E:$E, 0)),"N/A")} -> #NAME? | S9: {=_xludf.IFNA(INDEX(Sheet6!S:S, MATCH($E9, Sheet6!$E:$E, 0)),"N/A")} -> #NAME? | T9: {=_xludf.IFNA(INDEX(Sheet6!T:T, MATCH($E9, Sheet6!$E:$E, 0)),"N/A")} -> #NAME? | U9: {=_xludf.IFNA(INDEX(Sheet6!U:U, MATCH($E9, Sheet6!$E:$E, 0)),"N/A")} -> #NAME? | V9: {=_xludf.IFNA(INDEX(Sheet6!V:V, MATCH($E9, Sheet6!$E:$E, 0)),"N/A")} -> #NAME? | W9: {=_xludf.IFNA(INDEX(Sheet6!W:W, MATCH($E9, Sheet6!$E:$E, 0)),"N/A")} -> #NAME? | X9: {=_xludf.IFNA(INDEX(Sheet6!X:X, MATCH($E9, Sheet6!$E:$E, 0)),"N/A")} -> #NAME?
A10: {=_xludf.IFNA(INDEX(Sheet6!A:A, MATCH($E10, Sheet6!$E:$E, 0)),"N/A")} -> #NAME? | B10: {=_xludf.IFNA(INDEX(Sheet6!B:B, MATCH($E10, Sheet6!$E:$E, 0)),"N/A")} -> #NAME? | C10: {=_xludf.IFNA(INDEX(Sheet6!C:C, MATCH($E10, Sheet6!$E:$E, 0)),"N/A")} -> #NAME? | D10: {=_xludf.IFNA(INDEX(Sheet6!D:D, MATCH($E10, Sheet6!$E:$E, 0)),"N/A")} -> #NAME? | E10: 3885 | F10: PEOPLE OF THE PHILIPPINES VS. ANTONIO OLIQUINO | G10: 39947 | H10: 39947 | I10: {=_xludf.IFNA(INDEX(Sheet6!I:I, MATCH($E10, Sheet6!$E:$E, 0)),"N/A")} -> #NAME? | J10: {=_xludf.IFNA(INDEX(Sheet6!J:J, MATCH($E10, Sheet6!$E:$E, 0)),"N/A")} -> #NAME? | K10: {=_xludf.IFNA(INDEX(Sheet6!K:K, MATCH($E10, Sheet6!$E:$E, 0)),"N/A")} -> #NAME? | L10: {=_xludf.IFNA(INDEX(Sheet6!L:L, MATCH($E10, Sheet6!$E:$E, 0)),"N/A")} -> #NAME? | M10: {=_xludf.IFNA(INDEX(Sheet6!M:M, MATCH($E10, Sheet6!$E:$E, 0)),"N/A")} -> #NAME? | N10: {=_xludf.IFNA(INDEX(Sheet6!N:N, MATCH($E10, Sheet6!$E:$E, 0)),"N/A")} -> #NAME? | O10: GRAVE ORAL DEFAMATION | P10: {=_xludf.IFNA(INDEX(Sheet6!P:P, MATCH($E10, Sheet6!$E:$E, 0)),"N/A")} -> #NAME? | Q10: {=_xludf.IFNA(INDEX(Sheet6!Q:Q, MATCH($E10, Sheet6!$E:$E, 0)),"N/A")} -> #NAME? | R10: {=_xludf.IFNA(INDEX(Sheet6!R:R, MATCH($E10, Sheet6!$E:$E, 0)),"N/A")} -> #NAME? | S10: {=_xludf.IFNA(INDEX(Sheet6!S:S, MATCH($E10, Sheet6!$E:$E, 0)),"N/A")} -> #NAME? | T10: {=_xludf.IFNA(INDEX(Sheet6!T:T, MATCH($E10, Sheet6!$E:$E, 0)),"N/A")} -> #NAME? | U10: {=_xludf.IFNA(INDEX(Sheet6!U:U, MATCH($E10, Sheet6!$E:$E, 0)),"N/A")} -> #NAME? | V10: {=_xludf.IFNA(INDEX(Sheet6!V:V, MATCH($E10, Sheet6!$E:$E, 0)),"N/A")} -> #NAME? | W10: {=_xludf.IFNA(INDEX(Sheet6!W:W, MATCH($E10, Sheet6!$E:$E, 0)),"N/A")} -> #NAME? | X10: {=_xludf.IFNA(INDEX(Sheet6!X:X, MATCH($E10, Sheet6!$E:$E, 0)),"N/A")} -> #NAME?
A11: {=_xludf.IFNA(INDEX(Sheet6!A:A, MATCH($E11, Sheet6!$E:$E, 0)),"N/A")} -> #NAME? | B11: {=_xludf.IFNA(INDEX(Sheet6!B:B, MATCH($E11, Sheet6!$E:$E, 0)),"N/A")} -> #NAME? | C11: {=_xludf.IFNA(INDEX(Sheet6!C:C, MATCH($E11, Sheet6!$E:$E, 0)),"N/A")} -> #NAME? | D11: {=_xludf.IFNA(INDEX(Sheet6!D:D, MATCH($E11, Sheet6!$E:$E, 0)),"N/A")} -> #NAME? | E11: 3886 | F11: PEOPLE OF THE PHILIPPINES VS. ARMANDO ALMOURA | G11: 39955 | H11: 39955 | I11: {=_xludf.IFNA(INDEX(Sheet6!I:I, MATCH($E11, Sheet6!$E:$E, 0)),"N/A")} -> #NAME? | J11: {=_xludf.IFNA(INDEX(Sheet6!J:J, MATCH($E11, Sheet6!$E:$E, 0)),"N/A")} -> #NAME? | K11: {=_xludf.IFNA(INDEX(Sheet6!K:K, MATCH($E11, Sheet6!$E:$E, 0)),"N/A")} -> #NAME? | L11: {=_xludf.IFNA(INDEX(Sheet6!L:L, MATCH($E11, Sheet6!$E:$E, 0)),"N/A")} -> #NAME? | M11: {=_xludf.IFNA(INDEX(Sheet6!M:M, MATCH($E11, Sheet6!$E:$E, 0)),"N/A")} -> #NAME? | N11: {=_xludf.IFNA(INDEX(Sheet6!N:N, MATCH($E11, Sheet6!$E:$E, 0)),"N/A")} -> #NAME? | O11: ATTEMPTED HOMICIDE | P11: {=_xludf.IFNA(INDEX(Sheet6!P:P, MATCH($E11, Sheet6!$E:$E, 0)),"N/A")} -> #NAME? | Q11: {=_xludf.IFNA(INDEX(Sheet6!Q:Q, MATCH($E11, Sheet6!$E:$E, 0)),"N/A")} -> #NAME? | R11: {=_xludf.IFNA(INDEX(Sheet6!R:R, MATCH($E11, Sheet6!$E:$E, 0)),"N/A")} -> #NAME? | S11: {=_xludf.IFNA(INDEX(Sheet6!S:S, MATCH($E11, Sheet6!$E:$E, 0)),"N/A")} -> #NAME? | T11: {=_xludf.IFNA(INDEX(Sheet6!T:T, MATCH($E11, Sheet6!$E:$E, 0)),"N/A")} -> #NAME? | U11: {=_xludf.IFNA(INDEX(Sheet6!U:U, MATCH($E11, Sheet6!$E:$E, 0)),"N/A")} -> #NAME? | V11: {=_xludf.IFNA(INDEX(Sheet6!V:V, MATCH($E11, Sheet6!$E:$E, 0)),"N/A")} -> #NAME? | W11: {=_xludf.IFNA(INDEX(Sheet6!W:W, MATCH($E11, Sheet6!$E:$E, 0)),"N/A")} -> #NAME? | X11: {=_xludf.IFNA(INDEX(Sheet6!X:X, MATCH($E11, Sheet6!$E:$E, 0)),"N/A")} -> #NAME?
A12: {=_xludf.IFNA(INDEX(Sheet6!A:A, MATCH($E12, Sheet6!$E:$E, 0)),"N/A")} -> #NAME? | B12: {=_xludf.IFNA(INDEX(Sheet6!B:B, MATCH($E12, Sheet6!$E:$E, 0)),"N/A")} -> #NAME? | C12: {=_xludf.IFNA(INDEX(Sheet6!C:C, MATCH($E12, Sheet6!$E:$E, 0)),"N/A")} -> #NAME? | D12: {=_xludf.IFNA(INDEX(Sheet6!D:D, MATCH($E12, Sheet6!$E:$E, 0)),"N/A")} -> #NAME? | E12: 3887 | F12: PEOPLE OF THE PHILIPPINES VS. RICKY APATAN | G12: 39974 | H12: 39974 | I12: {=_xludf.IFNA(INDEX(Sheet6!I:I, MATCH($E12, Sheet6!$E:$E, 0)),"N/A")} -> #NAME? | J12: {=_xludf.IFNA(INDEX(Sheet6!J:J, MATCH($E12, Sheet6!$E:$E, 0)),"N/A")} -> #NAME? | K12: {=_xludf.IFNA(INDEX(Sheet6!K:K, MATCH($E12, Sheet6!$E:$E, 0)),"N/A")} -> #NAME? | L12: {=_xludf.IFNA(INDEX(Sheet6!L:L, MATCH($E12, Sheet6!$E:$E, 0)),"N/A")} -> #NAME? | M12: {=_xludf.IFNA(INDEX(Sheet6!M:M, MATCH($E12, Sheet6!$E:$E, 0)),"N/A")} -> #NAME? | N12: {=_xludf.IFNA(INDEX(Sheet6!N:N, MATCH($E12, Sheet6!$E:$E, 0)),"N/A")} -> #NAME? | O12: SLIGHT PHYSICAN INJURIES | P12: {=_xludf.IFNA(INDEX(Sheet6!P:P, MATCH($E12, Sheet6!$E:$E, 0)),"N/A")} -> #NAME? | Q12: {=_xludf.IFNA(INDEX(Sheet6!Q:Q, MATCH($E12, Sheet6!$E:$E, 0)),"N/A")} -> #NAME? | R12: {=_xludf.IFNA(INDEX(Sheet6!R:R, MATCH($E12, Sheet6!$E:$E, 0)),"N/A")} -> #NAME? | S12: {=_xludf.IFNA(INDEX(Sheet6!S:S, MATCH($E12, Sheet6!$E:$E, 0)),"N/A")} -> #NAME? | T12: {=_xludf.IFNA(INDEX(Sheet6!T:T, MATCH($E12, Sheet6!$E:$E, 0)),"N/A")} -> #NAME? | U12: {=_xludf.IFNA(INDEX(Sheet6!U:U, MATCH($E12, Sheet6!$E:$E, 0)),"N/A")} -> #NAME? | V12: {=_xludf.IFNA(INDEX(Sheet6!V:V, MATCH($E12, Sheet6!$E:$E, 0)),"N/A")} -> #NAME? | W12: {=_xludf.IFNA(INDEX(Sheet6!W:W, MATCH($E12, Sheet6!$E:$E, 0)),"N/A")} -> #NAME? | X12: {=_xludf.IFNA(INDEX(Sheet6!X:X, MATCH($E12, Sheet6!$E:$E, 0)),"N/A")} -> #NAME?
A13: {=_xludf.IFNA(INDEX(Sheet6!A:A, MATCH($E13, Sheet6!$E:$E, 0)),"N/A")} -> #NAME? | B13: {=_xludf.IFNA(INDEX(Sheet6!B:B, MATCH($E13, Sheet6!$E:$E, 0)),"N/A")} -> #NAME? | C13: {=_xludf.IFNA(INDEX(Sheet6!C:C, MATCH($E13, Sheet6!$E:$E, 0)),"N/A")} -> #NAME? | D13: {=_xludf.IFNA(INDEX(Sheet6!D:D, MATCH($E13, Sheet6!$E:$E, 0)),"N/A")} -> #NAME? | E13: 3888 | F13: PEOPLE OF THE PHILIPPINES VS. JAIRUS Y. ARAPAN | G13: 39981 | H13: 39981 | I13: {=_xludf.IFNA(INDEX(Sheet6!I:I, MATCH($E13, Sheet6!$E:$E, 0)),"N/A")} -> #NAME? | J13: {=_xludf.IFNA(INDEX(Sheet6!J:J, MATCH($E13, Sheet6!$E:$E, 0)),"N/A")} -> #NAME? | K13: {=_xludf.IFNA(INDEX(Sheet6!K:K, MATCH($E13, Sheet6!$E:$E, 0)),"N/A")} -> #NAME? | L13: {=_xludf.IFNA(INDEX(Sheet6!L:L, MATCH($E13, Sheet6!$E:$E, 0)),"N/A")} -> #NAME? | M13: {=_xludf.IFNA(INDEX(Sheet6!M:M, MATCH($E13, Sheet6!$E:$E, 0)),"N/A")} -> #NAME? | N13: {=_xludf.IFNA(INDEX(Sheet6!N:N, MATCH($E13, Sheet6!$E:$E, 0)),"N/A")} -> #NAME? | O13: SLIGHT PHYSICAN INJURIES | P13: {=_xludf.IFNA(INDEX(Sheet6!P:P, MATCH($E13, Sheet6!$E:$E, 0)),"N/A")} -> #NAME? | Q13: {=_xludf.IFNA(INDEX(Sheet6!Q:Q, MATCH($E13, Sheet6!$E:$E, 0)),"N/A")} -> #NAME? | R13: {=_xludf.IFNA(INDEX(Sheet6!R:R, MATCH($E13, Sheet6!$E:$E, 0)),"N/A")} -> #NAME? | S13: {=_xludf.IFNA(INDEX(Sheet6!S:S, MATCH($E13, Sheet6!$E:$E, 0)),"N/A")} -> #NAME? | T13: {=_xludf.IFNA(INDEX(Sheet6!T:T, MATCH($E13, Sheet6!$E:$E, 0)),"N/A")} -> #NAME? | U13: {=_xludf.IFNA(INDEX(Sheet6!U:U, MATCH($E13, Sheet6!$E:$E, 0)),"N/A")} -> #NAME? | V13: {=_xludf.IFNA(INDEX(Sheet6!V:V, MATCH($E13, Sheet6!$E:$E, 0)),"N/A")} -> #NAME? | W13: {=_xludf.IFNA(INDEX(Sheet6!W:W, MATCH($E13, Sheet6!$E:$E, 0)),"N/A")} -> #NAME? | X13: {=_xludf.IFNA(INDEX(Sheet6!X:X, MATCH($E13, Sheet6!$E:$E, 0)),"N/A")} -> #NAME?
A14: {=_xludf.IFNA(INDEX(Sheet6!A:A, MATCH($E14, Sheet6!$E:$E, 0)),"N/A")} -> #NAME? | B14: {=_xludf.IFNA(INDEX(Sheet6!B:B, MATCH($E14, Sheet6!$E:$E, 0)),"N/A")} -> #NAME? | C14: {=_xludf.IFNA(INDEX(Sheet6!C:C, MATCH($E14, Sheet6!$E:$E, 0)),"N/A")} -> #NAME? | D14: {=_xludf.IFNA(INDEX(Sheet6!D:D, MATCH($E14, Sheet6!$E:$E, 0)),"N/A")} -> #NAME? | E14: 3889 | F14: PEOPLE OF THE PHILIPPINES VS. PASCASIO S. JALASAN JR. | G14: 40010 | H14: 40010 | I14: {=_xludf.IFNA(INDEX(Sheet6!I:I, MATCH($E14, Sheet6!$E:$E, 0)),"N/A")} -> #NAME? | J14: {=_xludf.IFNA(INDEX(Sheet6!J:J, MATCH($E14, Sheet6!$E:$E, 0)),"N/A")} -> #NAME? | K14: {=_xludf.IFNA(INDEX(Sheet6!K:K, MATCH($E14, Sheet6!$E:$E, 0)),"N/A")} -> #NAME? | L14: {=_xludf.IFNA(INDEX(Sheet6!L:L, MATCH($E14, Sheet6!$E:$E, 0)),"N/A")} -> #NAME? | M14: {=_xludf.IFNA(INDEX(Sheet6!M:M, MATCH($E14, Sheet6!$E:$E, 0)),"N/A")} -> #NAME? | N14: {=_xludf.IFNA(INDEX(Sheet6!N:N, MATCH($E14, Sheet6!$E:$E, 0)),"N/A")} -> #NAME? | O14: RECKLESS IMPRUDENCE RESULTING TO LESS SERIOUS PHYSICAL INJURIES | P14: {=_xludf.IFNA(INDEX(Sheet6!P:P, MATCH($E14, Sheet6!$E:$E, 0)),"N/A")} -> #NAME? | Q14: {=_xludf.IFNA(INDEX(Sheet6!Q:Q, MATCH($E14, Sheet6!$E:$E, 0)),"N/A")} -> #NAME? | R14: {=_xludf.IFNA(INDEX(Sheet6!R:R, MATCH($E14, Sheet6!$E:$E, 0)),"N/A")} -> #NAME? | S14: {=_xludf.IFNA(INDEX(Sheet6!S:S, MATCH($E14, Sheet6!$E:$E, 0)),"N/A")} -> #NAME? | T14: {=_xludf.IFNA(INDEX(Sheet6!T:T, MATCH($E14, Sheet6!$E:$E, 0)),"N/A")} -> #NAME? | U14: {=_xludf.IFNA(INDEX(Sheet6!U:U, MATCH($E14, Sheet6!$E:$E, 0)),"N/A")} -> #NAME? | V14: {=_xludf.IFNA(INDEX(Sheet6!V:V, MATCH($E14, Sheet6!$E:$E, 0)),"N/A")} -> #NAME? | W14: {=_xludf.IFNA(INDEX(Sheet6!W:W, MATCH($E14, Sheet6!$E:$E, 0)),"N/A")} -> #NAME? | X14: {=_xludf.IFNA(INDEX(Sheet6!X:X, MATCH($E14, Sheet6!$E:$E, 0)),"N/A")} -> #NAME?
... A30: {=_xludf.IFNA(INDEX(Sheet6!A:A, MATCH($E30, Sheet6!$E:$E, 0)),"N/A")} -> #NAME? | B30: {=_xludf.IFNA(INDEX(Sheet6!B:B, MATCH($E30, Sheet6!$E:$E, 0)),"N/A")} -> #NAME? | C30: {=_xludf.IFNA(INDEX(Sheet6!C:C, MATCH($E30, Sheet6!$E:$E, 0)),"N/A")} -> #NAME? | D30: {=_xludf.IFNA(INDEX(Sheet6!D:D, MATCH($E30, Sheet6!$E:$E, 0)),"N/A")} -> #NAME? | E30: 3905 | F30: PEOPLE OF THE PHILIPPINES VS. VILMA MADRAZO | G30: 40280 | H30: 40280 | I30: {=_xludf.IFNA(INDEX(Sheet6!I:I, MATCH($E30, Sheet6!$E:$E, 0)),"N/A")} -> #NAME? | J30: {=_xludf.IFNA(INDEX(Sheet6!J:J, MATCH($E30, Sheet6!$E:$E, 0)),"N/A")} -> #NAME? | K30: {=_xludf.IFNA(INDEX(Sheet6!K:K, MATCH($E30, Sheet6!$E:$E, 0)),"N/A")} -> #NAME? | L30: {=_xludf.IFNA(INDEX(Sheet6!L:L, MATCH($E30, Sheet6!$E:$E, 0)),"N/A")} -> #NAME? | M30: {=_xludf.IFNA(INDEX(Sheet6!M:M, MATCH($E30, Sheet6!$E:$E, 0)),"N/A")} -> #NAME? | N30: {=_xludf.IFNA(INDEX(Sheet6!N:N, MATCH($E30, Sheet6!$E:$E, 0)),"N/A")} -> #NAME? | O30: OTHER FORM OF TRESPASS | P30: {=_xludf.IFNA(INDEX(Sheet6!P:P, MATCH($E30, Sheet6!$E:$E, 0)),"N/A")} -> #NAME? | Q30: {=_xludf.IFNA(INDEX(Sheet6!Q:Q, MATCH($E30, Sheet6!$E:$E, 0)),"N/A")} -> #NAME? | R30: {=_xludf.IFNA(INDEX(Sheet6!R:R, MATCH($E30, Sheet6!$E:$E, 0)),"N/A")} -> #NAME? | S30: {=_xludf.IFNA(INDEX(Sheet6!S:S, MATCH($E30, Sheet6!$E:$E, 0)),"N/A")} -> #NAME? | T30: {=_xludf.IFNA(INDEX(Sheet6!T:T, MATCH($E30, Sheet6!$E:$E, 0)),"N/A")} -> #NAME? | U30: {=_xludf.IFNA(INDEX(Sheet6!U:U, MATCH($E30, Sheet6!$E:$E, 0)),"N/A")} -> #NAME? | V30: {=_xludf.IFNA(INDEX(Sheet6!V:V, MATCH($E30, Sheet6!$E:$E, 0)),"N/A")} -> #NAME? | W30: {=_xludf.IFNA(INDEX(Sheet6!W:W, MATCH($E30, Sheet6!$E:$E, 0)),"N/A")} -> #NAME? | X30: {=_xludf.IFNA(INDEX(Sheet6!X:X, MATCH($E30, Sheet6!$E:$E, 0)),"N/A")} -> #NAME?
A31: {=_xludf.IFNA(INDEX(Sheet6!A:A, MATCH($E31, Sheet6!$E:$E, 0)),"N/A")} -> #NAME? | B31: {=_xludf.IFNA(INDEX(Sheet6!B:B, MATCH($E31, Sheet6!$E:$E, 0)),"N/A")} -> #NAME? | C31: {=_xludf.IFNA(INDEX(Sheet6!C:C, MATCH($E31, Sheet6!$E:$E, 0)),"N/A")} -> #NAME? | D31: {=_xludf.IFNA(INDEX(Sheet6!D:D, MATCH($E31, Sheet6!$E:$E, 0)),"N/A")} -> #NAME? | E31: 3906 | F31: PEOPLE OF THE PHILIPPINES VS. CHARLITO BADAJOS Y OCHETE | G31: 40380 | H31: 40380 | I31: {=_xludf.IFNA(INDEX(Sheet6!I:I, MATCH($E31, Sheet6!$E:$E, 0)),"N/A")} -> #NAME? | J31: {=_xludf.IFNA(INDEX(Sheet6!J:J, MATCH($E31, Sheet6!$E:$E, 0)),"N/A")} -> #NAME? | K31: {=_xludf.IFNA(INDEX(Sheet6!K:K, MATCH($E31, Sheet6!$E:$E, 0)),"N/A")} -> #NAME? | L31: {=_xludf.IFNA(INDEX(Sheet6!L:L, MATCH($E31, Sheet6!$E:$E, 0)),"N/A")} -> #NAME? | M31: {=_xludf.IFNA(INDEX(Sheet6!M:M, MATCH($E31, Sheet6!$E:$E, 0)),"N/A")} -> #NAME? | N31: {=_xludf.IFNA(INDEX(Sheet6!N:N, MATCH($E31, Sheet6!$E:$E, 0)),"N/A")} -> #NAME? | P31: {=_xludf.IFNA(INDEX(Sheet6!P:P, MATCH($E31, Sheet6!$E:$E, 0)),"N/A")} -> #NAME? | Q31: {=_xludf.IFNA(INDEX(Sheet6!Q:Q, MATCH($E31, Sheet6!$E:$E, 0)),"N/A")} -> #NAME? | R31: {=_xludf.IFNA(INDEX(Sheet6!R:R, MATCH($E31, Sheet6!$E:$E, 0)),"N/A")} -> #NAME? | S31: {=_xludf.IFNA(INDEX(Sheet6!S:S, MATCH($E31, Sheet6!$E:$E, 0)),"N/A")} -> #NAME? | T31: {=_xludf.IFNA(INDEX(Sheet6!T:T, MATCH($E31, Sheet6!$E:$E, 0)),"N/A")} -> #NAME? | U31: {=_xludf.IFNA(INDEX(Sheet6!U:U, MATCH($E31, Sheet6!$E:$E, 0)),"N/A")} -> #NAME? | V31: {=_xludf.IFNA(INDEX(Sheet6!V:V, MATCH($E31, Sheet6!$E:$E, 0)),"N/A")} -> #NAME? | W31: {=_xludf.IFNA(INDEX(Sheet6!W:W, MATCH($E31, Sheet6!$E:$E, 0)),"N/A")} -> #NAME? | X31: {=_xludf.IFNA(INDEX(Sheet6!X:X, MATCH($E31, Sheet6!$E:$E, 0)),"N/A")} -> #NAME?
A32: {=_xludf.IFNA(INDEX(Sheet6!A:A, MATCH($E32, Sheet6!$E:$E, 0)),"N/A")} -> #NAME? | B32: {=_xludf.IFNA(INDEX(Sheet6!B:B, MATCH($E32, Sheet6!$E:$E, 0)),"N/A")} -> #NAME? | C32: {=_xludf.IFNA(INDEX(Sheet6!C:C, MATCH($E32, Sheet6!$E:$E, 0)),"N/A")} -> #NAME? | D32: {=_xludf.IFNA(INDEX(Sheet6!D:D, MATCH($E32, Sheet6!$E:$E, 0)),"N/A")} -> #NAME? | E32: 3907 | F32: PEOPLE OF THE PHILIPPINES VS. OCITE DEVERA | G32: 40297 | H32: 40297 | I32: {=_xludf.IFNA(INDEX(Sheet6!I:I, MATCH($E32, Sheet6!$E:$E, 0)),"N/A")} -> #NAME? | J32: {=_xludf.IFNA(INDEX(Sheet6!J:J, MATCH($E32, Sheet6!$E:$E, 0)),"N/A")} -> #NAME? | K32: {=_xludf.IFNA(INDEX(Sheet6!K:K, MATCH($E32, Sheet6!$E:$E, 0)),"N/A")} -> #NAME? | L32: {=_xludf.IFNA(INDEX(Sheet6!L:L, MATCH($E32, Sheet6!$E:$E, 0)),"N/A")} -> #NAME? | M32: {=_xludf.IFNA(INDEX(Sheet6!M:M, MATCH($E32, Sheet6!$E:$E, 0)),"N/A")} -> #NAME? | N32: {=_xludf.IFNA(INDEX(Sheet6!N:N, MATCH($E32, Sheet6!$E:$E, 0)),"N/A")} -> #NAME? | O32: MALICIOUS MISCHIEF | P32: {=_xludf.IFNA(INDEX(Sheet6!P:P, MATCH($E32, Sheet6!$E:$E, 0)),"N/A")} -> #NAME? | Q32: {=_xludf.IFNA(INDEX(Sheet6!Q:Q, MATCH($E32, Sheet6!$E:$E, 0)),"N/A")} -> #NAME? | R32: {=_xludf.IFNA(INDEX(Sheet6!R:R, MATCH($E32, Sheet6!$E:$E, 0)),"N/A")} -> #NAME? | S32: {=_xludf.IFNA(INDEX(Sheet6!S:S, MATCH($E32, Sheet6!$E:$E, 0)),"N/A")} -> #NAME? | T32: {=_xludf.IFNA(INDEX(Sheet6!T:T, MATCH($E32, Sheet6!$E:$E, 0)),"N/A")} -> #NAME? | U32: {=_xludf.IFNA(INDEX(Sheet6!U:U, MATCH($E32, Sheet6!$E:$E, 0)),"N/A")} -> #NAME? | V32: {=_xludf.IFNA(INDEX(Sheet6!V:V, MATCH($E32, Sheet6!$E:$E, 0)),"N/A")} -> #NAME? | W32: {=_xludf.IFNA(INDEX(Sheet6!W:W, MATCH($E32, Sheet6!$E:$E, 0)),"N/A")} -> #NAME? | X32: {=_xludf.IFNA(INDEX(Sheet6!X:X, MATCH($E32, Sheet6!$E:$E, 0)),"N/A")} -> #NAME?
A33: {=_xludf.IFNA(INDEX(Sheet6!A:A, MATCH($E33, Sheet6!$E:$E, 0)),"N/A")} -> #NAME? | B33: {=_xludf.IFNA(INDEX(Sheet6!B:B, MATCH($E33, Sheet6!$E:$E, 0)),"N/A")} -> #NAME? | C33: {=_xludf.IFNA(INDEX(Sheet6!C:C, MATCH($E33, Sheet6!$E:$E, 0)),"N/A")} -> #NAME? | D33: {=_xludf.IFNA(INDEX(Sheet6!D:D, MATCH($E33, Sheet6!$E:$E, 0)),"N/A")} -> #NAME? | E33: 3908 | F33: PEOPLE OF THE PHILIPPINES VS. BERNABE PUNAS | G33: 40304 | H33: 40304 | I33: {=_xludf.IFNA(INDEX(Sheet6!I:I, MATCH($E33, Sheet6!$E:$E, 0)),"N/A")} -> #NAME? | J33: {=_xludf.IFNA(INDEX(Sheet6!J:J, MATCH($E33, Sheet6!$E:$E, 0)),"N/A")} -> #NAME? | K33: {=_xludf.IFNA(INDEX(Sheet6!K:K, MATCH($E33, Sheet6!$E:$E, 0)),"N/A")} -> #NAME? | L33: {=_xludf.IFNA(INDEX(Sheet6!L:L, MATCH($E33, Sheet6!$E:$E, 0)),"N/A")} -> #NAME? | M33: {=_xludf.IFNA(INDEX(Sheet6!M:M, MATCH($E33, Sheet6!$E:$E, 0)),"N/A")} -> #NAME? | N33: {=_xludf.IFNA(INDEX(Sheet6!N:N, MATCH($E33, Sheet6!$E:$E, 0)),"N/A")} -> #NAME? | O33: ATTEMPTED HOMICIDE | P33: {=_xludf.IFNA(INDEX(Sheet6!P:P, MATCH($E33, Sheet6!$E:$E, 0)),"N/A")} -> #NAME? | Q33: {=_xludf.IFNA(INDEX(Sheet6!Q:Q, MATCH($E33, Sheet6!$E:$E, 0)),"N/A")} -> #NAME? | R33: {=_xludf.IFNA(INDEX(Sheet6!R:R, MATCH($E33, Sheet6!$E:$E, 0)),"N/A")} -> #NAME? | S33: {=_xludf.IFNA(INDEX(Sheet6!S:S, MATCH($E33, Sheet6!$E:$E, 0)),"N/A")} -> #NAME? | T33: {=_xludf.IFNA(INDEX(Sheet6!T:T, MATCH($E33, Sheet6!$E:$E, 0)),"N/A")} -> #NAME? | U33: {=_xludf.IFNA(INDEX(Sheet6!U:U, MATCH($E33, Sheet6!$E:$E, 0)),"N/A")} -> #NAME? | V33: {=_xludf.IFNA(INDEX(Sheet6!V:V, MATCH($E33, Sheet6!$E:$E, 0)),"N/A")} -> #NAME? | W33: {=_xludf.IFNA(INDEX(Sheet6!W:W, MATCH($E33, Sheet6!$E:$E, 0)),"N/A")} -> #NAME? | X33: {=_xludf.IFNA(INDEX(Sheet6!X:X, MATCH($E33, Sheet6!$E:$E, 0)),"N/A")} -> #NAME?
A34: {=_xludf.IFNA(INDEX(Sheet6!A:A, MATCH($E34, Sheet6!$E:$E, 0)),"N/A")} -> #NAME? | B34: {=_xludf.IFNA(INDEX(Sheet6!B:B, MATCH($E34, Sheet6!$E:$E, 0)),"N/A")} -> #NAME? | C34: {=_xludf.IFNA(INDEX(Sheet6!C:C, MATCH($E34, Sheet6!$E:$E, 0)),"N/A")} -> #NAME? | D34: {=_xludf.IFNA(INDEX(Sheet6!D:D, MATCH($E34, Sheet6!$E:$E, 0)),"N/A")} -> #NAME? | E34: 3909 | F34: PEOPLE OF THE PHILIPPINES VS. NICOLE WILSON TAGHOP | G34: 40319 | H34: 40319 | I34: {=_xludf.IFNA(INDEX(Sheet6!I:I, MATCH($E34, Sheet6!$E:$E, 0)),"N/A")} -> #NAME? | J34: {=_xludf.IFNA(INDEX(Sheet6!J:J, MATCH($E34, Sheet6!$E:$E, 0)),"N/A")} -> #NAME? | K34: {=_xludf.IFNA(INDEX(Sheet6!K:K, MATCH($E34, Sheet6!$E:$E, 0)),"N/A")} -> #NAME? | L34: {=_xludf.IFNA(INDEX(Sheet6!L:L, MATCH($E34, Sheet6!$E:$E, 0)),"N/A")} -> #NAME? | M34: {=_xludf.IFNA(INDEX(Sheet6!M:M, MATCH($E34, Sheet6!$E:$E, 0)),"N/A")} -> #NAME? | N34: {=_xludf.IFNA(INDEX(Sheet6!N:N, MATCH($E34, Sheet6!$E:$E, 0)),"N/A")} -> #NAME? | O34: RECKLESS IMPRUDENCE RESULTING TO LESS SERIOUS PYSICAL INJURIES & DAMAGE TO PROPERTY | P34: {=_xludf.IFNA(INDEX(Sheet6!P:P, MATCH($E34, Sheet6!$E:$E, 0)),"N/A")} -> #NAME? | Q34: {=_xludf.IFNA(INDEX(Sheet6!Q:Q, MATCH($E34, Sheet6!$E:$E, 0)),"N/A")} -> #NAME? | R34: {=_xludf.IFNA(INDEX(Sheet6!R:R, MATCH($E34, Sheet6!$E:$E, 0)),"N/A")} -> #NAME? | S34: {=_xludf.IFNA(INDEX(Sheet6!S:S, MATCH($E34, Sheet6!$E:$E, 0)),"N/A")} -> #NAME? | T34: {=_xludf.IFNA(INDEX(Sheet6!T:T, MATCH($E34, Sheet6!$E:$E, 0)),"N/A")} -> #NAME? | U34: {=_xludf.IFNA(INDEX(Sheet6!U:U, MATCH($E34, Sheet6!$E:$E, 0)),"N/A")} -> #NAME? | V34: {=_xludf.IFNA(INDEX(Sheet6!V:V, MATCH($E34, Sheet6!$E:$E, 0)),"N/A")} -> #NAME? | W34: {=_xludf.IFNA(INDEX(Sheet6!W:W, MATCH($E34, Sheet6!$E:$E, 0)),"N/A")} -> #NAME? | X34: {=_xludf.IFNA(INDEX(Sheet6!X:X, MATCH($E34, Sheet6!$E:$E, 0)),"N/A")} -> #NAME?
A35: {=_xludf.IFNA(INDEX(Sheet6!A:A, MATCH($E35, Sheet6!$E:$E, 0)),"N/A")} -> #NAME? | B35: {=_xludf.IFNA(INDEX(Sheet6!B:B, MATCH($E35, Sheet6!$E:$E, 0)),"N/A")} -> #NAME? | C35: {=_xludf.IFNA(INDEX(Sheet6!C:C, MATCH($E35, Sheet6!$E:$E, 0)),"N/A")} -> #NAME? | D35: {=_xludf.IFNA(INDEX(Sheet6!D:D, MATCH($E35, Sheet6!$E:$E, 0)),"N/A")} -> #NAME? | E35: 3910 | F35: PEOPLE OF THE PHILIPPINES VS. ROGELIO PAGARAN Y CAGAS | G35: 40324 | H35: 40324 | I35: {=_xludf.IFNA(INDEX(Sheet6!I:I, MATCH($E35, Sheet6!$E:$E, 0)),"N/A")} -> #NAME? | J35: {=_xludf.IFNA(INDEX(Sheet6!J:J, MATCH($E35, Sheet6!$E:$E, 0)),"N/A")} -> #NAME? | K35: {=_xludf.IFNA(INDEX(Sheet6!K:K, MATCH($E35, Sheet6!$E:$E, 0)),"N/A")} -> #NAME? | L35: {=_xludf.IFNA(INDEX(Sheet6!L:L, MATCH($E35, Sheet6!$E:$E, 0)),"N/A")} -> #NAME? | M35: {=_xludf.IFNA(INDEX(Sheet6!M:M, MATCH($E35, Sheet6!$E:$E, 0)),"N/A")} -> #NAME? | N35: {=_xludf.IFNA(INDEX(Sheet6!N:N, MATCH($E35, Sheet6!$E:$E, 0)),"N/A")} -> #NAME? | O35: ATTEMPTED HOMICIDE | P35: {=_xludf.IFNA(INDEX(Sheet6!P:P, MATCH($E35, Sheet6!$E:$E, 0)),"N/A")} -> #NAME? | Q35: {=_xludf.IFNA(INDEX(Sheet6!Q:Q, MATCH($E35, Sheet6!$E:$E, 0)),"N/A")} -> #NAME? | R35: {=_xludf.IFNA(INDEX(Sheet6!R:R, MATCH($E35, Sheet6!$E:$E, 0)),"N/A")} -> #NAME? | S35: {=_xludf.IFNA(INDEX(Sheet6!S:S, MATCH($E35, Sheet6!$E:$E, 0)),"N/A")} -> #NAME? | T35: {=_xludf.IFNA(INDEX(Sheet6!T:T, MATCH($E35, Sheet6!$E:$E, 0)),"N/A")} -> #NAME? | U35: {=_xludf.IFNA(INDEX(Sheet6!U:U, MATCH($E35, Sheet6!$E:$E, 0)),"N/A")} -> #NAME? | V35: {=_xludf.IFNA(INDEX(Sheet6!V:V, MATCH($E35, Sheet6!$E:$E, 0)),"N/A")} -> #NAME? | W35: {=_xludf.IFNA(INDEX(Sheet6!W:W, MATCH($E35, Sheet6!$E:$E, 0)),"N/A")} -> #NAME? | X35: {=_xludf.IFNA(INDEX(Sheet6!X:X, MATCH($E35, Sheet6!$E:$E, 0)),"N/A")} -> #NAME?
A36: {=_xludf.IFNA(INDEX(Sheet6!A:A, MATCH($E36, Sheet6!$E:$E, 0)),"N/A")} -> #NAME? | B36: {=_xludf.IFNA(INDEX(Sheet6!B:B, MATCH($E36, Sheet6!$E:$E, 0)),"N/A")} -> #NAME? | C36: {=_xludf.IFNA(INDEX(Sheet6!C:C, MATCH($E36, Sheet6!$E:$E, 0)),"N/A")} -> #NAME? | D36: {=_xludf.IFNA(INDEX(Sheet6!D:D, MATCH($E36, Sheet6!$E:$E, 0)),"N/A")} -> #NAME? | E36: 3911 | F36: PEOPLE OF THE PHILIPPINES VS. ROBERT PAUL COPELAND | G36: 40333 | H36: 40333 | I36: {=_xludf.IFNA(INDEX(Sheet6!I:I, MATCH($E36, Sheet6!$E:$E, 0)),"N/A")} -> #NAME? | J36: {=_xludf.IFNA(INDEX(Sheet6!J:J, MATCH($E36, Sheet6!$E:$E, 0)),"N/A")} -> #NAME? | K36: {=_xludf.IFNA(INDEX(Sheet6!K:K, MATCH($E36, Sheet6!$E:$E, 0)),"N/A")} -> #NAME? | L36: {=_xludf.IFNA(INDEX(Sheet6!L:L, MATCH($E36, Sheet6!$E:$E, 0)),"N/A")} -> #NAME? | M36: {=_xludf.IFNA(INDEX(Sheet6!M:M, MATCH($E36, Sheet6!$E:$E, 0)),"N/A")} -> #NAME? | N36: {=_xludf.IFNA(INDEX(Sheet6!N:N, MATCH($E36, Sheet6!$E:$E, 0)),"N/A")} -> #NAME? | O36: DIRECT ASSAULT OF A PERSON IN AUTHORITY | P36: {=_xludf.IFNA(INDEX(Sheet6!P:P, MATCH($E36, Sheet6!$E:$E, 0)),"N/A")} -> #NAME? | Q36: {=_xludf.IFNA(INDEX(Sheet6!Q:Q, MATCH($E36, Sheet6!$E:$E, 0)),"N/A")} -> #NAME? | R36: {=_xludf.IFNA(INDEX(Sheet6!R:R, MATCH($E36, Sheet6!$E:$E, 0)),"N/A")} -> #NAME? | S36: {=_xludf.IFNA(INDEX(Sheet6!S:S, MATCH($E36, Sheet6!$E:$E, 0)),"N/A")} -> #NAME? | T36: {=_xludf.IFNA(INDEX(Sheet6!T:T, MATCH($E36, Sheet6!$E:$E, 0)),"N/A")} -> #NAME? | U36: {=_xludf.IFNA(INDEX(Sheet6!U:U, MATCH($E36, Sheet6!$E:$E, 0)),"N/A")} -> #NAME? | V36: {=_xludf.IFNA(INDEX(Sheet6!V:V, MATCH($E36, Sheet6!$E:$E, 0)),"N/A")} -> #NAME? | W36: {=_xludf.IFNA(INDEX(Sheet6!W:W, MATCH($E36, Sheet6!$E:$E, 0)),"N/A")} -> #NAME? | X36: {=_xludf.IFNA(INDEX(Sheet6!X:X, MATCH($E36, Sheet6!$E:$E, 0)),"N/A")} -> #NAME?
A37: {=_xludf.IFNA(INDEX(Sheet6!A:A, MATCH($E37, Sheet6!$E:$E, 0)),"N/A")} -> #NAME? | B37: {=_xludf.IFNA(INDEX(Sheet6!B:B, MATCH($E37, Sheet6!$E:$E, 0)),"N/A")} -> #NAME? | C37: {=_xludf.IFNA(INDEX(Sheet6!C:C, MATCH($E37, Sheet6!$E:$E, 0)),"N/A")} -> #NAME? | D37: {=_xludf.IFNA(INDEX(Sheet6!D:D, MATCH($E37, Sheet6!$E:$E, 0)),"N/A")} -> #NAME? | E37: 3912 | F37: PEOPLE OF THE PHILIPPINES VS. ROBERT PAUL COPELAND | G37: 40333 | H37: 40333 | I37: {=_xludf.IFNA(INDEX(Sheet6!I:I, MATCH($E37, Sheet6!$E:$E, 0)),"N/A")} -> #NAME? | J37: {=_xludf.IFNA(INDEX(Sheet6!J:J, MATCH($E37, Sheet6!$E:$E, 0)),"N/A")} -> #NAME? | K37: {=_xludf.IFNA(INDEX(Sheet6!K:K, MATCH($E37, Sheet6!$E:$E, 0)),"N/A")} -> #NAME? | L37: {=_xludf.IFNA(INDEX(Sheet6!L:L, MATCH($E37, Sheet6!$E:$E, 0)),"N/A")} -> #NAME? | M37: {=_xludf.IFNA(INDEX(Sheet6!M:M, MATCH($E37, Sheet6!$E:$E, 0)),"N/A")} -> #NAME? | N37: {=_xludf.IFNA(INDEX(Sheet6!N:N, MATCH($E37, Sheet6!$E:$E, 0)),"N/A")} -> #NAME? | O37: RESISTANCE & DISOBEDIENCE TO AN AGENT OF A PERSON IN AUTHORITY | P37: {=_xludf.IFNA(INDEX(Sheet6!P:P, MATCH($E37, Sheet6!$E:$E, 0)),"N/A")} -> #NAME? | Q37: {=_xludf.IFNA(INDEX(Sheet6!Q:Q, MATCH($E37, Sheet6!$E:$E, 0)),"N/A")} -> #NAME? | R37: {=_xludf.IFNA(INDEX(Sheet6!R:R, MATCH($E37, Sheet6!$E:$E, 0)),"N/A")} -> #NAME? | S37: {=_xludf.IFNA(INDEX(Sheet6!S:S, MATCH($E37, Sheet6!$E:$E, 0)),"N/A")} -> #NAME? | T37: {=_xludf.IFNA(INDEX(Sheet6!T:T, MATCH($E37, Sheet6!$E:$E, 0)),"N/A")} -> #NAME? | U37: {=_xludf.IFNA(INDEX(Sheet6!U:U, MATCH($E37, Sheet6!$E:$E, 0)),"N/A")} -> #NAME? | V37: {=_xludf.IFNA(INDEX(Sheet6!V:V, MATCH($E37, Sheet6!$E:$E, 0)),"N/A")} -> #NAME? | W37: {=_xludf.IFNA(INDEX(Sheet6!W:W, MATCH($E37, Sheet6!$E:$E, 0)),"N/A")} -> #NAME? | X37: {=_xludf.IFNA(INDEX(Sheet6!X:X, MATCH($E37, Sheet6!$E:$E, 0)),"N/A")} -> #NAME?
A38: {=_xludf.IFNA(INDEX(Sheet6!A:A, MATCH($E38, Sheet6!$E:$E, 0)),"N/A")} -> #NAME? | B38: {=_xludf.IFNA(INDEX(Sheet6!B:B, MATCH($E38, Sheet6!$E:$E, 0)),"N/A")} -> #NAME? | C38: {=_xludf.IFNA(INDEX(Sheet6!C:C, MATCH($E38, Sheet6!$E:$E, 0)),"N/A")} -> #NAME? | D38: {=_xludf.IFNA(INDEX(Sheet6!D:D, MATCH($E38, Sheet6!$E:$E, 0)),"N/A")} -> #NAME? | E38: 3913 | F38: PEOPLE OF THE PHILIPPINES VS. CARLITO DE ASIS | G38: 40338 | H38: 40338 | I38: {=_xludf.IFNA(INDEX(Sheet6!I:I, MATCH($E38, Sheet6!$E:$E, 0)),"N/A")} -> #NAME? | J38: {=_xludf.IFNA(INDEX(Sheet6!J:J, MATCH($E38, Sheet6!$E:$E, 0)),"N/A")} -> #NAME? | K38: {=_xludf.IFNA(INDEX(Sheet6!K:K, MATCH($E38, Sheet6!$E:$E, 0)),"N/A")} -> #NAME? | L38: {=_xludf.IFNA(INDEX(Sheet6!L:L, MATCH($E38, Sheet6!$E:$E, 0)),"N/A")} -> #NAME? | M38: {=_xludf.IFNA(INDEX(Sheet6!M:M, MATCH($E38, Sheet6!$E:$E, 0)),"N/A")} -> #NAME? | N38: {=_xludf.IFNA(INDEX(Sheet6!N:N, MATCH($E38, Sheet6!$E:$E, 0)),"N/A")} -> #NAME? | O38: OTHER FORM OF TRESPASS | P38: {=_xludf.IFNA(INDEX(Sheet6!P:P, MATCH($E38, Sheet6!$E:$E, 0)),"N/A")} -> #NAME? | Q38: {=_xludf.IFNA(INDEX(Sheet6!Q:Q, MATCH($E38, Sheet6!$E:$E, 0)),"N/A")} -> #NAME? | R38: {=_xludf.IFNA(INDEX(Sheet6!R:R, MATCH($E38, Sheet6!$E:$E, 0)),"N/A")} -> #NAME? | S38: {=_xludf.IFNA(INDEX(Sheet6!S:S, MATCH($E38, Sheet6!$E:$E, 0)),"N/A")} -> #NAME? | T38: {=_xludf.IFNA(INDEX(Sheet6!T:T, MATCH($E38, Sheet6!$E:$E, 0)),"N/A")} -> #NAME? | U38: {=_xludf.IFNA(INDEX(Sheet6!U:U, MATCH($E38, Sheet6!$E:$E, 0)),"N/A")} -> #NAME? | V38: {=_xludf.IFNA(INDEX(Sheet6!V:V, MATCH($E38, Sheet6!$E:$E, 0)),"N/A")} -> #NAME? | W38: {=_xludf.IFNA(INDEX(Sheet6!W:W, MATCH($E38, Sheet6!$E:$E, 0)),"N/A")} -> #NAME? | X38: {=_xludf.IFNA(INDEX(Sheet6!X:X, MATCH($E38, Sheet6!$E:$E, 0)),"N/A")} -> #NAME?
A39: {=_xludf.IFNA(INDEX(Sheet6!A:A, MATCH($E39, Sheet6!$E:$E, 0)),"N/A")} -> #NAME? | B39: {=_xludf.IFNA(INDEX(Sheet6!B:B, MATCH($E39, Sheet6!$E:$E, 0)),"N/A")} -> #NAME? | C39: {=_xludf.IFNA(INDEX(Sheet6!C:C, MATCH($E39, Sheet6!$E:$E, 0)),"N/A")} -> #NAME? | D39: {=_xludf.IFNA(INDEX(Sheet6!D:D, MATCH($E39, Sheet6!$E:$E, 0)),"N/A")} -> #NAME? | E39: 3914 | F39: PEOPLE OF THE PHILIPPINES VS. CRISTINA RACIONERO Y PELINO | G39: 40364 | H39: 40364 | I39: {=_xludf.IFNA(INDEX(Sheet6!I:I, MATCH($E39, Sheet6!$E:$E, 0)),"N/A")} -> #NAME? | J39: {=_xludf.IFNA(INDEX(Sheet6!J:J, MATCH($E39, Sheet6!$E:$E, 0)),"N/A")} -> #NAME? | K39: {=_xludf.IFNA(INDEX(Sheet6!K:K, MATCH($E39, Sheet6!$E:$E, 0)),"N/A")} -> #NAME? | L39: {=_xludf.IFNA(INDEX(Sheet6!L:L, MATCH($E39, Sheet6!$E:$E, 0)),"N/A")} -> #NAME? | M39: {=_xludf.IFNA(INDEX(Sheet6!M:M, MATCH($E39, Sheet6!$E:$E, 0)),"N/A")} -> #NAME? | N39: {=_xludf.IFNA(INDEX(Sheet6!N:N, MATCH($E39, Sheet6!$E:$E, 0)),"N/A")} -> #NAME? | O39: SIMPLE IMPRUDENCE RESULTING TO DAMAGE TO PROPERTY | P39: {=_xludf.IFNA(INDEX(Sheet6!P:P, MATCH($E39, Sheet6!$E:$E, 0)),"N/A")} -> #NAME? | Q39: {=_xludf.IFNA(INDEX(Sheet6!Q:Q, MATCH($E39, Sheet6!$E:$E, 0)),"N/A")} -> #NAME? | R39: {=_xludf.IFNA(INDEX(Sheet6!R:R, MATCH($E39, Sheet6!$E:$E, 0)),"N/A")} -> #NAME? | S39: {=_xludf.IFNA(INDEX(Sheet6!S:S, MATCH($E39, Sheet6!$E:$E, 0)),"N/A")} -> #NAME? | T39: {=_xludf.IFNA(INDEX(Sheet6!T:T, MATCH($E39, Sheet6!$E:$E, 0)),"N/A")} -> #NAME? | U39: {=_xludf.IFNA(INDEX(Sheet6!U:U, MATCH($E39, Sheet6!$E:$E, 0)),"N/A")} -> #NAME? | V39: {=_xludf.IFNA(INDEX(Sheet6!V:V, MATCH($E39, Sheet6!$E:$E, 0)),"N/A")} -> #NAME? | W39: {=_xludf.IFNA(INDEX(Sheet6!W:W, MATCH($E39, Sheet6!$E:$E, 0)),"N/A")} -> #NAME? | X39: {=_xludf.IFNA(INDEX(Sheet6!X:X, MATCH($E39, Sheet6!$E:$E, 0)),"N/A")} -> #NAME?
A40: {=_xludf.IFNA(INDEX(Sheet6!A:A, MATCH($E40, Sheet6!$E:$E, 0)),"N/A")} -> #NAME? | B40: {=_xludf.IFNA(INDEX(Sheet6!B:B, MATCH($E40, Sheet6!$E:$E, 0)),"N/A")} -> #NAME? | C40: {=_xludf.IFNA(INDEX(Sheet6!C:C, MATCH($E40, Sheet6!$E:$E, 0)),"N/A")} -> #NAME? | D40: {=_xludf.IFNA(INDEX(Sheet6!D:D, MATCH($E40, Sheet6!$E:$E, 0)),"N/A")} -> #NAME? | E40: 3915 | F40: PEOPLE OF THE PHILIPPINES VS. CHARLITO SARABIA AKA CALOY | G40: 40395 | H40: 40395 | I40: {=_xludf.IFNA(INDEX(Sheet6!I:I, MATCH($E40, Sheet6!$E:$E, 0)),"N/A")} -> #NAME? | J40: {=_xludf.IFNA(INDEX(Sheet6!J:J, MATCH($E40, Sheet6!$E:$E, 0)),"N/A")} -> #NAME? | K40: {=_xludf.IFNA(INDEX(Sheet6!K:K, MATCH($E40, Sheet6!$E:$E, 0)),"N/A")} -> #NAME? | L40: {=_xludf.IFNA(INDEX(Sheet6!L:L, MATCH($E40, Sheet6!$E:$E, 0)),"N/A")} -> #NAME? | M40: {=_xludf.IFNA(INDEX(Sheet6!M:M, MATCH($E40, Sheet6!$E:$E, 0)),"N/A")} -> #NAME? | N40: {=_xludf.IFNA(INDEX(Sheet6!N:N, MATCH($E40, Sheet6!$E:$E, 0)),"N/A")} -> #NAME? | O40: MALICIOUS MISCHIEF | P40: {=_xludf.IFNA(INDEX(Sheet6!P:P, MATCH($E40, Sheet6!$E:$E, 0)),"N/A")} -> #NAME? | Q40: {=_xludf.IFNA(INDEX(Sheet6!Q:Q, MATCH($E40, Sheet6!$E:$E, 0)),"N/A")} -> #NAME? | R40: {=_xludf.IFNA(INDEX(Sheet6!R:R, MATCH($E40, Sheet6!$E:$E, 0)),"N/A")} -> #NAME? | S40: {=_xludf.IFNA(INDEX(Sheet6!S:S, MATCH($E40, Sheet6!$E:$E, 0)),"N/A")} -> #NAME? | T40: {=_xludf.IFNA(INDEX(Sheet6!T:T, MATCH($E40, Sheet6!$E:$E, 0)),"N/A")} -> #NAME? | U40: {=_xludf.IFNA(INDEX(Sheet6!U:U, MATCH($E40, Sheet6!$E:$E, 0)),"N/A")} -> #NAME? | V40: {=_xludf.IFNA(INDEX(Sheet6!V:V, MATCH($E40, Sheet6!$E:$E, 0)),"N/A")} -> #NAME? | W40: {=_xludf.IFNA(INDEX(Sheet6!W:W, MATCH($E40, Sheet6!$E:$E, 0)),"N/A")} -> #NAME? | X40: {=_xludf.IFNA(INDEX(Sheet6!X:X, MATCH($E40, Sheet6!$E:$E, 0)),"N/A")} -> #NAME?
A41: {=_xludf.IFNA(INDEX(Sheet6!A:A, MATCH($E41, Sheet6!$E:$E, 0)),"N/A")} -> #NAME? | B41: {=_xludf.IFNA(INDEX(Sheet6!B:B, MATCH($E41, Sheet6!$E:$E, 0)),"N/A")} -> #NAME? | C41: {=_xludf.IFNA(INDEX(Sheet6!C:C, MATCH($E41, Sheet6!$E:$E, 0)),"N/A")} -> #NAME? | D41: {=_xludf.IFNA(INDEX(Sheet6!D:D, MATCH($E41, Sheet6!$E:$E, 0)),"N/A")} -> #NAME? | E41: 3916 | F41: PEOPLE OF THE PHILIPPINES VS. CHARLITO SARABIA AKA CALOY, JONATHAN ENCENADA & JOHN ERIC BAUTISTA | G41: 40395 | H41: 40395 | I41: {=_xludf.IFNA(INDEX(Sheet6!I:I, MATCH($E41, Sheet6!$E:$E, 0)),"N/A")} -> #NAME? | J41: {=_xludf.IFNA(INDEX(Sheet6!J:J, MATCH($E41, Sheet6!$E:$E, 0)),"N/A")} -> #NAME? | K41: {=_xludf.IFNA(INDEX(Sheet6!K:K, MATCH($E41, Sheet6!$E:$E, 0)),"N/A")} -> #NAME? | L41: {=_xludf.IFNA(INDEX(Sheet6!L:L, MATCH($E41, Sheet6!$E:$E, 0)),"N/A")} -> #NAME? | M41: {=_xludf.IFNA(INDEX(Sheet6!M:M, MATCH($E41, Sheet6!$E:$E, 0)),"N/A")} -> #NAME? | N41: {=_xludf.IFNA(INDEX(Sheet6!N:N, MATCH($E41, Sheet6!$E:$E, 0)),"N/A")} -> #NAME? | O41: ATTEMPTED HOMICIDE | P41: {=_xludf.IFNA(INDEX(Sheet6!P:P, MATCH($E41, Sheet6!$E:$E, 0)),"N/A")} -> #NAME? | Q41: {=_xludf.IFNA(INDEX(Sheet6!Q:Q, MATCH($E41, Sheet6!$E:$E, 0)),"N/A")} -> #NAME? | R41: {=_xludf.IFNA(INDEX(Sheet6!R:R, MATCH($E41, Sheet6!$E:$E, 0)),"N/A")} -> #NAME? | S41: {=_xludf.IFNA(INDEX(Sheet6!S:S, MATCH($E41, Sheet6!$E:$E, 0)),"N/A")} -> #NAME? | T41: {=_xludf.IFNA(INDEX(Sheet6!T:T, MATCH($E41, Sheet6!$E:$E, 0)),"N/A")} -> #NAME? | U41: {=_xludf.IFNA(INDEX(Sheet6!U:U, MATCH($E41, Sheet6!$E:$E, 0)),"N/A")} -> #NAME? | V41: {=_xludf.IFNA(INDEX(Sheet6!V:V, MATCH($E41, Sheet6!$E:$E, 0)),"N/A")} -> #NAME? | W41: {=_xludf.IFNA(INDEX(Sheet6!W:W, MATCH($E41, Sheet6!$E:$E, 0)),"N/A")} -> #NAME? | X41: {=_xludf.IFNA(INDEX(Sheet6!X:X, MATCH($E41, Sheet6!$E:$E, 0)),"N/A")} -> #NAME?
A42: {=_xludf.IFNA(INDEX(Sheet6!A:A, MATCH($E42, Sheet6!$E:$E, 0)),"N/A")} -> #NAME? | B42: {=_xludf.IFNA(INDEX(Sheet6!B:B, MATCH($E42, Sheet6!$E:$E, 0)),"N/A")} -> #NAME? | C42: {=_xludf.IFNA(INDEX(Sheet6!C:C, MATCH($E42, Sheet6!$E:$E, 0)),"N/A")} -> #NAME? | D42: {=_xludf.IFNA(INDEX(Sheet6!D:D, MATCH($E42, Sheet6!$E:$E, 0)),"N/A")} -> #NAME? | E42: 3917 | F42: PEOPLE OF THE PHILIPPINES VS. CHARLITO SARABIA AKA CALOY, JONATHAN ENCENADA & JOHN ERIC BAUTISTA | G42: 40395 | H42: 40395 | I42: {=_xludf.IFNA(INDEX(Sheet6!I:I, MATCH($E42, Sheet6!$E:$E, 0)),"N/A")} -> #NAME? | J42: {=_xludf.IFNA(INDEX(Sheet6!J:J, MATCH($E42, Sheet6!$E:$E, 0)),"N/A")} -> #NAME? | K42: {=_xludf.IFNA(INDEX(Sheet6!K:K, MATCH($E42, Sheet6!$E:$E, 0)),"N/A")} -> #NAME? | L42: {=_xludf.IFNA(INDEX(Sheet6!L:L, MATCH($E42, Sheet6!$E:$E, 0)),"N/A")} -> #NAME? | M42: {=_xludf.IFNA(INDEX(Sheet6!M:M, MATCH($E42, Sheet6!$E:$E, 0)),"N/A")} -> #NAME? | N42: {=_xludf.IFNA(INDEX(Sheet6!N:N, MATCH($E42, Sheet6!$E:$E, 0)),"N/A")} -> #NAME? | O42: ATTEMPTED HOMICIDE | P42: {=_xludf.IFNA(INDEX(Sheet6!P:P, MATCH($E42, Sheet6!$E:$E, 0)),"N/A")} -> #NAME? | Q42: {=_xludf.IFNA(INDEX(Sheet6!Q:Q, MATCH($E42, Sheet6!$E:$E, 0)),"N/A")} -> #NAME? | R42: {=_xludf.IFNA(INDEX(Sheet6!R:R, MATCH($E42, Sheet6!$E:$E, 0)),"N/A")} -> #NAME? | S42: {=_xludf.IFNA(INDEX(Sheet6!S:S, MATCH($E42, Sheet6!$E:$E, 0)),"N/A")} -> #NAME? | T42: {=_xludf.IFNA(INDEX(Sheet6!T:T, MATCH($E42, Sheet6!$E:$E, 0)),"N/A")} -> #NAME? | U42: {=_xludf.IFNA(INDEX(Sheet6!U:U, MATCH($E42, Sheet6!$E:$E, 0)),"N/A")} -> #NAME? | V42: {=_xludf.IFNA(INDEX(Sheet6!V:V, MATCH($E42, Sheet6!$E:$E, 0)),"N/A")} -> #NAME? | W42: {=_xludf.IFNA(INDEX(Sheet6!W:W, MATCH($E42, Sheet6!$E:$E, 0)),"N/A")} -> #NAME? | X42: {=_xludf.IFNA(INDEX(Sheet6!X:X, MATCH($E42, Sheet6!$E:$E, 0)),"N/A")} -> #NAME?
A43: {=_xludf.IFNA(INDEX(Sheet6!A:A, MATCH($E43, Sheet6!$E:$E, 0)),"N/A")} -> #NAME? | B43: {=_xludf.IFNA(INDEX(Sheet6!B:B, MATCH($E43, Sheet6!$E:$E, 0)),"N/A")} -> #NAME? | C43: {=_xludf.IFNA(INDEX(Sheet6!C:C, MATCH($E43, Sheet6!$E:$E, 0)),"N/A")} -> #NAME? | D43: {=_xludf.IFNA(INDEX(Sheet6!D:D, MATCH($E43, Sheet6!$E:$E, 0)),"N/A")} -> #NAME? | E43: 3918 | F43: PEOPLE OF THE PHILIPPINES VS. JESSIE CABALTERA Y DIZON | G43: 40395 | H43: 40395 | I43: {=_xludf.IFNA(INDEX(Sheet6!I:I, MATCH($E43, Sheet6!$E:$E, 0)),"N/A")} -> #NAME? | J43: {=_xludf.IFNA(INDEX(Sheet6!J:J, MATCH($E43, Sheet6!$E:$E, 0)),"N/A")} -> #NAME? | K43: {=_xludf.IFNA(INDEX(Sheet6!K:K, MATCH($E43, Sheet6!$E:$E, 0)),"N/A")} -> #NAME? | L43: {=_xludf.IFNA(INDEX(Sheet6!L:L, MATCH($E43, Sheet6!$E:$E, 0)),"N/A")} -> #NAME? | M43: {=_xludf.IFNA(INDEX(Sheet6!M:M, MATCH($E43, Sheet6!$E:$E, 0)),"N/A")} -> #NAME? | N43: {=_xludf.IFNA(INDEX(Sheet6!N:N, MATCH($E43, Sheet6!$E:$E, 0)),"N/A")} -> #NAME? | O43: MALICIOUS MISCHIEF | P43: {=_xludf.IFNA(INDEX(Sheet6!P:P, MATCH($E43, Sheet6!$E:$E, 0)),"N/A")} -> #NAME? | Q43: {=_xludf.IFNA(INDEX(Sheet6!Q:Q, MATCH($E43, Sheet6!$E:$E, 0)),"N/A")} -> #NAME? | R43: {=_xludf.IFNA(INDEX(Sheet6!R:R, MATCH($E43, Sheet6!$E:$E, 0)),"N/A")} -> #NAME? | S43: {=_xludf.IFNA(INDEX(Sheet6!S:S, MATCH($E43, Sheet6!$E:$E, 0)),"N/A")} -> #NAME? | T43: {=_xludf.IFNA(INDEX(Sheet6!T:T, MATCH($E43, Sheet6!$E:$E, 0)),"N/A")} -> #NAME? | U43: {=_xludf.IFNA(INDEX(Sheet6!U:U, MATCH($E43, Sheet6!$E:$E, 0)),"N/A")} -> #NAME? | V43: {=_xludf.IFNA(INDEX(Sheet6!V:V, MATCH($E43, Sheet6!$E:$E, 0)),"N/A")} -> #NAME? | W43: {=_xludf.IFNA(INDEX(Sheet6!W:W, MATCH($E43, Sheet6!$E:$E, 0)),"N/A")} -> #NAME? | X43: {=_xludf.IFNA(INDEX(Sheet6!X:X, MATCH($E43, Sheet6!$E:$E, 0)),"N/A")} -> #NAME?
... A76: {=_xludf.IFNA(INDEX(Sheet6!A:A, MATCH($E76, Sheet6!$E:$E, 0)),"N/A")} -> #NAME? | B76: {=_xludf.IFNA(INDEX(Sheet6!B:B, MATCH($E76, Sheet6!$E:$E, 0)),"N/A")} -> #NAME? | C76: {=_xludf.IFNA(INDEX(Sheet6!C:C, MATCH($E76, Sheet6!$E:$E, 0)),"N/A")} -> #NAME? | D76: {=_xludf.IFNA(INDEX(Sheet6!D:D, MATCH($E76, Sheet6!$E:$E, 0)),"N/A")} -> #NAME? | E76: 3951 | F76: PEOPLE OF THE PHILIPPINES VS. JOSELITO EROY Y MIRAS & RANDY BARBOSA Y AURO, PATRIC ALOUZO, WESTLY AMORA & ALIAS MARMAR | G76: 40613 | H76: 40613 | I76: {=_xludf.IFNA(INDEX(Sheet6!I:I, MATCH($E76, Sheet6!$E:$E, 0)),"N/A")} -> #NAME? | J76: {=_xludf.IFNA(INDEX(Sheet6!J:J, MATCH($E76, Sheet6!$E:$E, 0)),"N/A")} -> #NAME? | K76: {=_xludf.IFNA(INDEX(Sheet6!K:K, MATCH($E76, Sheet6!$E:$E, 0)),"N/A")} -> #NAME? | L76: {=_xludf.IFNA(INDEX(Sheet6!L:L, MATCH($E76, Sheet6!$E:$E, 0)),"N/A")} -> #NAME? | M76: {=_xludf.IFNA(INDEX(Sheet6!M:M, MATCH($E76, Sheet6!$E:$E, 0)),"N/A")} -> #NAME? | N76: {=_xludf.IFNA(INDEX(Sheet6!N:N, MATCH($E76, Sheet6!$E:$E, 0)),"N/A")} -> #NAME? | O76: LESS SERIOUS PHYSICAL INJURIES | P76: {=_xludf.IFNA(INDEX(Sheet6!P:P, MATCH($E76, Sheet6!$E:$E, 0)),"N/A")} -> #NAME? | Q76: {=_xludf.IFNA(INDEX(Sheet6!Q:Q, MATCH($E76, Sheet6!$E:$E, 0)),"N/A")} -> #NAME? | R76: {=_xludf.IFNA(INDEX(Sheet6!R:R, MATCH($E76, Sheet6!$E:$E, 0)),"N/A")} -> #NAME? | S76: {=_xludf.IFNA(INDEX(Sheet6!S:S, MATCH($E76, Sheet6!$E:$E, 0)),"N/A")} -> #NAME? | T76: {=_xludf.IFNA(INDEX(Sheet6!T:T, MATCH($E76, Sheet6!$E:$E, 0)),"N/A")} -> #NAME? | U76: {=_xludf.IFNA(INDEX(Sheet6!U:U, MATCH($E76, Sheet6!$E:$E, 0)),"N/A")} -> #NAME? | V76: {=_xludf.IFNA(INDEX(Sheet6!V:V, MATCH($E76, Sheet6!$E:$E, 0)),"N/A")} -> #NAME? | W76: {=_xludf.IFNA(INDEX(Sheet6!W:W, MATCH($E76, Sheet6!$E:$E, 0)),"N/A")} -> #NAME? | X76: {=_xludf.IFNA(INDEX(Sheet6!X:X, MATCH($E76, Sheet6!$E:$E, 0)),"N/A")} -> #NAME?
A77: {=_xludf.IFNA(INDEX(Sheet6!A:A, MATCH($E77, Sheet6!$E:$E, 0)),"N/A")} -> #NAME? | B77: {=_xludf.IFNA(INDEX(Sheet6!B:B, MATCH($E77, Sheet6!$E:$E, 0)),"N/A")} -> #NAME? | C77: {=_xludf.IFNA(INDEX(Sheet6!C:C, MATCH($E77, Sheet6!$E:$E, 0)),"N/A")} -> #NAME? | D77: {=_xludf.IFNA(INDEX(Sheet6!D:D, MATCH($E77, Sheet6!$E:$E, 0)),"N/A")} -> #NAME? | E77: 3952 | F77: PEOPLE OF THE PHILIPPINES VS. MELANIE B. ORCALES | G77: 40608 | H77: 40608 | I77: {=_xludf.IFNA(INDEX(Sheet6!I:I, MATCH($E77, Sheet6!$E:$E, 0)),"N/A")} -> #NAME? | J77: {=_xludf.IFNA(INDEX(Sheet6!J:J, MATCH($E77, Sheet6!$E:$E, 0)),"N/A")} -> #NAME? | K77: {=_xludf.IFNA(INDEX(Sheet6!K:K, MATCH($E77, Sheet6!$E:$E, 0)),"N/A")} -> #NAME? | L77: {=_xludf.IFNA(INDEX(Sheet6!L:L, MATCH($E77, Sheet6!$E:$E, 0)),"N/A")} -> #NAME? | M77: {=_xludf.IFNA(INDEX(Sheet6!M:M, MATCH($E77, Sheet6!$E:$E, 0)),"N/A")} -> #NAME? | N77: {=_xludf.IFNA(INDEX(Sheet6!N:N, MATCH($E77, Sheet6!$E:$E, 0)),"N/A")} -> #NAME? | P77: {=_xludf.IFNA(INDEX(Sheet6!P:P, MATCH($E77, Sheet6!$E:$E, 0)),"N/A")} -> #NAME? | Q77: {=_xludf.IFNA(INDEX(Sheet6!Q:Q, MATCH($E77, Sheet6!$E:$E, 0)),"N/A")} -> #NAME? | R77: {=_xludf.IFNA(INDEX(Sheet6!R:R, MATCH($E77, Sheet6!$E:$E, 0)),"N/A")} -> #NAME? | S77: {=_xludf.IFNA(INDEX(Sheet6!S:S, MATCH($E77, Sheet6!$E:$E, 0)),"N/A")} -> #NAME? | T77: {=_xludf.IFNA(INDEX(Sheet6!T:T, MATCH($E77, Sheet6!$E:$E, 0)),"N/A")} -> #NAME? | U77: {=_xludf.IFNA(INDEX(Sheet6!U:U, MATCH($E77, Sheet6!$E:$E, 0)),"N/A")} -> #NAME? | V77: {=_xludf.IFNA(INDEX(Sheet6!V:V, MATCH($E77, Sheet6!$E:$E, 0)),"N/A")} -> #NAME? | W77: {=_xludf.IFNA(INDEX(Sheet6!W:W, MATCH($E77, Sheet6!$E:$E, 0)),"N/A")} -> #NAME? | X77: {=_xludf.IFNA(INDEX(Sheet6!X:X, MATCH($E77, Sheet6!$E:$E, 0)),"N/A")} -> #NAME?
A78: {=_xludf.IFNA(INDEX(Sheet6!A:A, MATCH($E78, Sheet6!$E:$E, 0)),"N/A")} -> #NAME? | B78: {=_xludf.IFNA(INDEX(Sheet6!B:B, MATCH($E78, Sheet6!$E:$E, 0)),"N/A")} -> #NAME? | C78: {=_xludf.IFNA(INDEX(Sheet6!C:C, MATCH($E78, Sheet6!$E:$E, 0)),"N/A")} -> #NAME? | D78: {=_xludf.IFNA(INDEX(Sheet6!D:D, MATCH($E78, Sheet6!$E:$E, 0)),"N/A")} -> #NAME? | E78: 3953 | F78: PEOPLE OF THE PHILIPPINES VS. SOLEDAD RIVERA Y BASA & MANNY RIVERA | G78: 40630 | H78: 40630 | I78: {=_xludf.IFNA(INDEX(Sheet6!I:I, MATCH($E78, Sheet6!$E:$E, 0)),"N/A")} -> #NAME? | J78: {=_xludf.IFNA(INDEX(Sheet6!J:J, MATCH($E78, Sheet6!$E:$E, 0)),"N/A")} -> #NAME? | K78: {=_xludf.IFNA(INDEX(Sheet6!K:K, MATCH($E78, Sheet6!$E:$E, 0)),"N/A")} -> #NAME? | L78: {=_xludf.IFNA(INDEX(Sheet6!L:L, MATCH($E78, Sheet6!$E:$E, 0)),"N/A")} -> #NAME? | M78: {=_xludf.IFNA(INDEX(Sheet6!M:M, MATCH($E78, Sheet6!$E:$E, 0)),"N/A")} -> #NAME? | N78: {=_xludf.IFNA(INDEX(Sheet6!N:N, MATCH($E78, Sheet6!$E:$E, 0)),"N/A")} -> #NAME? | O78: VIOLATION OF ART. 315 OF RPC | P78: {=_xludf.IFNA(INDEX(Sheet6!P:P, MATCH($E78, Sheet6!$E:$E, 0)),"N/A")} -> #NAME? | Q78: {=_xludf.IFNA(INDEX(Sheet6!Q:Q, MATCH($E78, Sheet6!$E:$E, 0)),"N/A")} -> #NAME? | R78: {=_xludf.IFNA(INDEX(Sheet6!R:R, MATCH($E78, Sheet6!$E:$E, 0)),"N/A")} -> #NAME? | S78: {=_xludf.IFNA(INDEX(Sheet6!S:S, MATCH($E78, Sheet6!$E:$E, 0)),"N/A")} -> #NAME? | T78: {=_xludf.IFNA(INDEX(Sheet6!T:T, MATCH($E78, Sheet6!$E:$E, 0)),"N/A")} -> #NAME? | U78: {=_xludf.IFNA(INDEX(Sheet6!U:U, MATCH($E78, Sheet6!$E:$E, 0)),"N/A")} -> #NAME? | V78: {=_xludf.IFNA(INDEX(Sheet6!V:V, MATCH($E78, Sheet6!$E:$E, 0)),"N/A")} -> #NAME? | W78: {=_xludf.IFNA(INDEX(Sheet6!W:W, MATCH($E78, Sheet6!$E:$E, 0)),"N/A")} -> #NAME? | X78: {=_xludf.IFNA(INDEX(Sheet6!X:X, MATCH($E78, Sheet6!$E:$E, 0)),"N/A")} -> #NAME?
A79: {=_xludf.IFNA(INDEX(Sheet6!A:A, MATCH($E79, Sheet6!$E:$E, 0)),"N/A")} -> #NAME? | B79: {=_xludf.IFNA(INDEX(Sheet6!B:B, MATCH($E79, Sheet6!$E:$E, 0)),"N/A")} -> #NAME? | C79: {=_xludf.IFNA(INDEX(Sheet6!C:C, MATCH($E79, Sheet6!$E:$E, 0)),"N/A")} -> #NAME? | D79: {=_xludf.IFNA(INDEX(Sheet6!D:D, MATCH($E79, Sheet6!$E:$E, 0)),"N/A")} -> #NAME? | E79: 3954 | F79: PEOPLE OF THE PHILIPPINES VS. BENJAMIN HUERA | G79: 40630 | H79: 40630 | I79: {=_xludf.IFNA(INDEX(Sheet6!I:I, MATCH($E79, Sheet6!$E:$E, 0)),"N/A")} -> #NAME? | J79: {=_xludf.IFNA(INDEX(Sheet6!J:J, MATCH($E79, Sheet6!$E:$E, 0)),"N/A")} -> #NAME? | K79: {=_xludf.IFNA(INDEX(Sheet6!K:K, MATCH($E79, Sheet6!$E:$E, 0)),"N/A")} -> #NAME? | L79: {=_xludf.IFNA(INDEX(Sheet6!L:L, MATCH($E79, Sheet6!$E:$E, 0)),"N/A")} -> #NAME? | M79: {=_xludf.IFNA(INDEX(Sheet6!M:M, MATCH($E79, Sheet6!$E:$E, 0)),"N/A")} -> #NAME? | N79: {=_xludf.IFNA(INDEX(Sheet6!N:N, MATCH($E79, Sheet6!$E:$E, 0)),"N/A")} -> #NAME? | O79: SIMPLE ORAL DEFAMATION | P79: {=_xludf.IFNA(INDEX(Sheet6!P:P, MATCH($E79, Sheet6!$E:$E, 0)),"N/A")} -> #NAME? | Q79: {=_xludf.IFNA(INDEX(Sheet6!Q:Q, MATCH($E79, Sheet6!$E:$E, 0)),"N/A")} -> #NAME? | R79: {=_xludf.IFNA(INDEX(Sheet6!R:R, MATCH($E79, Sheet6!$E:$E, 0)),"N/A")} -> #NAME? | S79: {=_xludf.IFNA(INDEX(Sheet6!S:S, MATCH($E79, Sheet6!$E:$E, 0)),"N/A")} -> #NAME? | T79: {=_xludf.IFNA(INDEX(Sheet6!T:T, MATCH($E79, Sheet6!$E:$E, 0)),"N/A")} -> #NAME? | U79: {=_xludf.IFNA(INDEX(Sheet6!U:U, MATCH($E79, Sheet6!$E:$E, 0)),"N/A")} -> #NAME? | V79: {=_xludf.IFNA(INDEX(Sheet6!V:V, MATCH($E79, Sheet6!$E:$E, 0)),"N/A")} -> #NAME? | W79: {=_xludf.IFNA(INDEX(Sheet6!W:W, MATCH($E79, Sheet6!$E:$E, 0)),"N/A")} -> #NAME? | X79: {=_xludf.IFNA(INDEX(Sheet6!X:X, MATCH($E79, Sheet6!$E:$E, 0)),"N/A")} -> #NAME?
A80: {=_xludf.IFNA(INDEX(Sheet6!A:A, MATCH($E80, Sheet6!$E:$E, 0)),"N/A")} -> #NAME? | B80: {=_xludf.IFNA(INDEX(Sheet6!B:B, MATCH($E80, Sheet6!$E:$E, 0)),"N/A")} -> #NAME? | C80: {=_xludf.IFNA(INDEX(Sheet6!C:C, MATCH($E80, Sheet6!$E:$E, 0)),"N/A")} -> #NAME? | D80: {=_xludf.IFNA(INDEX(Sheet6!D:D, MATCH($E80, Sheet6!$E:$E, 0)),"N/A")} -> #NAME? | E80: 3955 | F80: PEOPLE OF THE PHILIPPINES VS. DANILLO CALUNSAG Y BAGNOL | G80: 40633 | H80: 40633 | I80: {=_xludf.IFNA(INDEX(Sheet6!I:I, MATCH($E80, Sheet6!$E:$E, 0)),"N/A")} -> #NAME? | J80: {=_xludf.IFNA(INDEX(Sheet6!J:J, MATCH($E80, Sheet6!$E:$E, 0)),"N/A")} -> #NAME? | K80: {=_xludf.IFNA(INDEX(Sheet6!K:K, MATCH($E80, Sheet6!$E:$E, 0)),"N/A")} -> #NAME? | L80: {=_xludf.IFNA(INDEX(Sheet6!L:L, MATCH($E80, Sheet6!$E:$E, 0)),"N/A")} -> #NAME? | M80: {=_xludf.IFNA(INDEX(Sheet6!M:M, MATCH($E80, Sheet6!$E:$E, 0)),"N/A")} -> #NAME? | N80: {=_xludf.IFNA(INDEX(Sheet6!N:N, MATCH($E80, Sheet6!$E:$E, 0)),"N/A")} -> #NAME? | O80: SLIGHT PHYSICAN INJURIES | P80: {=_xludf.IFNA(INDEX(Sheet6!P:P, MATCH($E80, Sheet6!$E:$E, 0)),"N/A")} -> #NAME? | Q80: {=_xludf.IFNA(INDEX(Sheet6!Q:Q, MATCH($E80, Sheet6!$E:$E, 0)),"N/A")} -> #NAME? | R80: {=_xludf.IFNA(INDEX(Sheet6!R:R, MATCH($E80, Sheet6!$E:$E, 0)),"N/A")} -> #NAME? | S80: {=_xludf.IFNA(INDEX(Sheet6!S:S, MATCH($E80, Sheet6!$E:$E, 0)),"N/A")} -> #NAME? | T80: {=_xludf.IFNA(INDEX(Sheet6!T:T, MATCH($E80, Sheet6!$E:$E, 0)),"N/A")} -> #NAME? | U80: {=_xludf.IFNA(INDEX(Sheet6!U:U, MATCH($E80, Sheet6!$E:$E, 0)),"N/A")} -> #NAME? | V80: {=_xludf.IFNA(INDEX(Sheet6!V:V, MATCH($E80, Sheet6!$E:$E, 0)),"N/A")} -> #NAME? | W80: {=_xludf.IFNA(INDEX(Sheet6!W:W, MATCH($E80, Sheet6!$E:$E, 0)),"N/A")} -> #NAME? | X80: {=_xludf.IFNA(INDEX(Sheet6!X:X, MATCH($E80, Sheet6!$E:$E, 0)),"N/A")} -> #NAME?
A81: {=_xludf.IFNA(INDEX(Sheet6!A:A, MATCH($E81, Sheet6!$E:$E, 0)),"N/A")} -> #NAME? | B81: {=_xludf.IFNA(INDEX(Sheet6!B:B, MATCH($E81, Sheet6!$E:$E, 0)),"N/A")} -> #NAME? | C81: {=_xludf.IFNA(INDEX(Sheet6!C:C, MATCH($E81, Sheet6!$E:$E, 0)),"N/A")} -> #NAME? | D81: {=_xludf.IFNA(INDEX(Sheet6!D:D, MATCH($E81, Sheet6!$E:$E, 0)),"N/A")} -> #NAME? | E81: 3956 | F81: PEOPLE OF THE PHILIPPINES VS. MICHAEL TABADA | G81: 40659 | H81: 40659 | I81: {=_xludf.IFNA(INDEX(Sheet6!I:I, MATCH($E81, Sheet6!$E:$E, 0)),"N/A")} -> #NAME? | J81: {=_xludf.IFNA(INDEX(Sheet6!J:J, MATCH($E81, Sheet6!$E:$E, 0)),"N/A")} -> #NAME? | K81: {=_xludf.IFNA(INDEX(Sheet6!K:K, MATCH($E81, Sheet6!$E:$E, 0)),"N/A")} -> #NAME? | L81: {=_xludf.IFNA(INDEX(Sheet6!L:L, MATCH($E81, Sheet6!$E:$E, 0)),"N/A")} -> #NAME? | M81: {=_xludf.IFNA(INDEX(Sheet6!M:M, MATCH($E81, Sheet6!$E:$E, 0)),"N/A")} -> #NAME? | N81: {=_xludf.IFNA(INDEX(Sheet6!N:N, MATCH($E81, Sheet6!$E:$E, 0)),"N/A")} -> #NAME? | O81: ATTEMPTED ARSON | P81: {=_xludf.IFNA(INDEX(Sheet6!P:P, MATCH($E81, Sheet6!$E:$E, 0)),"N/A")} -> #NAME? | Q81: {=_xludf.IFNA(INDEX(Sheet6!Q:Q, MATCH($E81, Sheet6!$E:$E, 0)),"N/A")} -> #NAME? | R81: {=_xludf.IFNA(INDEX(Sheet6!R:R, MATCH($E81, Sheet6!$E:$E, 0)),"N/A")} -> #NAME? | S81: {=_xludf.IFNA(INDEX(Sheet6!S:S, MATCH($E81, Sheet6!$E:$E, 0)),"N/A")} -> #NAME? | T81: {=_xludf.IFNA(INDEX(Sheet6!T:T, MATCH($E81, Sheet6!$E:$E, 0)),"N/A")} -> #NAME? | U81: {=_xludf.IFNA(INDEX(Sheet6!U:U, MATCH($E81, Sheet6!$E:$E, 0)),"N/A")} -> #NAME? | V81: {=_xludf.IFNA(INDEX(Sheet6!V:V, MATCH($E81, Sheet6!$E:$E, 0)),"N/A")} -> #NAME? | W81: {=_xludf.IFNA(INDEX(Sheet6!W:W, MATCH($E81, Sheet6!$E:$E, 0)),"N/A")} -> #NAME? | X81: {=_xludf.IFNA(INDEX(Sheet6!X:X, MATCH($E81, Sheet6!$E:$E, 0)),"N/A")} -> #NAME?
